2021-07-18 08:27:08,940 - __main__ - INFO - Got the following arguments: ['our_newtest.py', '0.045', '1', '0.2', '8', '../CMineMR-Mapreduce-algorithm-to-extract-coverage-patterns-master/dataset/synthetic.txt', 'varying_mincs_mushroom_0.2_ultrmaxprodummy']
2021-07-18 08:27:14,868 - __main__ - INFO - started mining
2021-07-18 08:27:14,868 - __main__ - INFO - reading transactional data
2021-07-18 08:27:15,350 - __main__ - INFO - transactions size: 13738144
2021-07-18 08:27:15,350 - __main__ - INFO - First level mining
2021-07-18 08:27:18,995 - __main__ - INFO - Got first level patterns : 17  writing to file
2021-07-18 08:27:18,997 - __main__ - INFO - Generating second level candidateset
2021-07-18 08:27:19,183 - __main__ - INFO - saving 2 level patterns
2021-07-18 08:27:19,183 - __main__ - INFO - found 136 patterns
2021-07-18 08:27:19,183 - __main__ - INFO - computing patterns for level : 3
2021-07-18 08:27:19,638 - __main__ - INFO - saving 3 level patterns
2021-07-18 08:27:19,638 - __main__ - INFO - found 639 patterns
2021-07-18 08:27:19,638 - __main__ - INFO - computing patterns for level : 4
2021-07-18 08:27:20,104 - __main__ - INFO - saving 4 level patterns
2021-07-18 08:27:20,105 - __main__ - INFO - found 1782 patterns
2021-07-18 08:27:20,105 - __main__ - INFO - computing patterns for level : 5
2021-07-18 08:27:20,973 - __main__ - INFO - saving 5 level patterns
2021-07-18 08:27:20,973 - __main__ - INFO - found 2107 patterns
2021-07-18 08:27:20,974 - __main__ - INFO - computing patterns for level : 6
2021-07-18 08:27:22,051 - __main__ - INFO - saving 6 level patterns
2021-07-18 08:27:22,051 - __main__ - INFO - found 556 patterns
2021-07-18 08:27:22,051 - __main__ - INFO - computing patterns for level : 7
2021-07-18 08:27:22,381 - __main__ - INFO - saving 7 level patterns
2021-07-18 08:27:22,381 - __main__ - INFO - found 9 patterns
2021-07-18 08:27:22,381 - __main__ - INFO - computing patterns for level : 8
2021-07-18 08:27:22,527 - __main__ - INFO - saving 8 level patterns
2021-07-18 08:27:22,527 - __main__ - INFO - found 0 patterns
2021-07-18 08:27:22,527 - __main__ - INFO - computing patterns for level : 9
2021-07-18 08:27:22,680 - __main__ - INFO - saving 9 level patterns
2021-07-18 08:27:22,761 - __main__ - INFO - total time taken: 7.8934326171875
2021-07-18 08:27:22,762 - root - INFO - broadcast size:3754307
shuffle read:404898
shuffle write:400292
2021-07-18 08:41:53,568 - __main__ - INFO - Got the following arguments: ['our_newtest.py', '0.05', '1', '0.2', '8', '../CMineMR-Mapreduce-algorithm-to-extract-coverage-patterns-master/dataset/mushroom.txt', 'varying_mincs_mushroom_0.2_ultrmaxprodummy']
2021-07-18 08:41:59,488 - __main__ - INFO - started mining
2021-07-18 08:41:59,489 - __main__ - INFO - reading transactional data
2021-07-18 08:41:59,573 - __main__ - INFO - transactions size: 2151101
2021-07-18 08:41:59,573 - __main__ - INFO - First level mining
2021-07-18 08:42:01,967 - __main__ - INFO - Got first level patterns : 73  writing to file
2021-07-18 08:42:01,969 - __main__ - INFO - Generating second level candidateset
2021-07-18 08:42:02,260 - __main__ - INFO - saving 2 level patterns
2021-07-18 08:42:02,260 - __main__ - INFO - found 881 patterns
2021-07-18 08:42:02,260 - __main__ - INFO - computing patterns for level : 3
2021-07-18 08:42:02,508 - __main__ - INFO - saving 3 level patterns
2021-07-18 08:42:02,508 - __main__ - INFO - found 3575 patterns
2021-07-18 08:42:02,508 - __main__ - INFO - computing patterns for level : 4
2021-07-18 08:42:02,763 - __main__ - INFO - saving 4 level patterns
2021-07-18 08:42:02,764 - __main__ - INFO - found 6146 patterns
2021-07-18 08:42:02,764 - __main__ - INFO - computing patterns for level : 5
2021-07-18 08:42:03,097 - __main__ - INFO - saving 5 level patterns
2021-07-18 08:42:03,098 - __main__ - INFO - found 5110 patterns
2021-07-18 08:42:03,098 - __main__ - INFO - computing patterns for level : 6
2021-07-18 08:42:03,438 - __main__ - INFO - saving 6 level patterns
2021-07-18 08:42:03,439 - __main__ - INFO - found 2186 patterns
2021-07-18 08:42:03,440 - __main__ - INFO - computing patterns for level : 7
2021-07-18 08:42:03,709 - __main__ - INFO - saving 7 level patterns
2021-07-18 08:42:03,709 - __main__ - INFO - found 480 patterns
2021-07-18 08:42:03,709 - __main__ - INFO - computing patterns for level : 8
2021-07-18 08:42:03,836 - __main__ - INFO - saving 8 level patterns
2021-07-18 08:42:03,836 - __main__ - INFO - found 49 patterns
2021-07-18 08:42:03,836 - __main__ - INFO - computing patterns for level : 9
2021-07-18 08:42:03,943 - __main__ - INFO - saving 9 level patterns
2021-07-18 08:42:03,943 - __main__ - INFO - found 1 patterns
2021-07-18 08:42:03,943 - __main__ - INFO - computing patterns for level : 10
2021-07-18 08:42:04,069 - __main__ - INFO - saving 10 level patterns
2021-07-18 08:42:04,069 - __main__ - INFO - found 0 patterns
2021-07-18 08:42:04,069 - __main__ - INFO - computing patterns for level : 11
2021-07-18 08:42:04,181 - __main__ - INFO - saving 11 level patterns
2021-07-18 08:42:04,191 - __main__ - INFO - total time taken: 4.702777147293091
2021-07-18 08:42:04,192 - root - INFO - broadcast size:558345
shuffle read:1446914
shuffle write:1415579
2021-07-18 08:52:29,971 - __main__ - INFO - Got the following arguments: ['our_newtest.py', '0.05', '1', '0.2', '8', '../CMineMR-Mapreduce-algorithm-to-extract-coverage-patterns-master/dataset/bmspos.txt', 'varying_mincs_mushroom_0.2_ultrmaxprodummy']
2021-07-18 08:52:35,388 - __main__ - INFO - started mining
2021-07-18 08:52:35,389 - __main__ - INFO - reading transactional data
2021-07-18 08:52:35,636 - __main__ - INFO - transactions size: 8368681
2021-07-18 08:52:35,636 - __main__ - INFO - First level mining
2021-07-18 08:52:38,420 - __main__ - INFO - Got first level patterns : 29  writing to file
2021-07-18 08:52:38,422 - __main__ - INFO - Generating second level candidateset
2021-07-18 08:52:38,702 - __main__ - INFO - saving 2 level patterns
2021-07-18 08:52:38,702 - __main__ - INFO - found 175 patterns
2021-07-18 08:52:38,702 - __main__ - INFO - computing patterns for level : 3
2021-07-18 08:52:39,163 - __main__ - INFO - saving 3 level patterns
2021-07-18 08:52:39,163 - __main__ - INFO - found 135 patterns
2021-07-18 08:52:39,164 - __main__ - INFO - computing patterns for level : 4
2021-07-18 08:52:39,315 - __main__ - INFO - saving 4 level patterns
2021-07-18 08:52:39,316 - __main__ - INFO - found 0 patterns
2021-07-18 08:52:39,316 - __main__ - INFO - computing patterns for level : 5
2021-07-18 08:52:39,427 - __main__ - INFO - saving 5 level patterns
2021-07-18 08:52:39,491 - __main__ - INFO - total time taken: 4.102949380874634
2021-07-18 08:52:39,492 - root - INFO - broadcast size:2964751
shuffle read:16037
shuffle write:10009
2021-07-18 09:26:19,519 - __main__ - INFO - Got the following arguments: ['our_newtest.py', '0.065', '1', '0.2', '8', '../CMineMR-Mapreduce-algorithm-to-extract-coverage-patterns-master/dataset/bmspos.txt', 'varying_mincs_mushroom_0.2_ultrmaxprodummy']
2021-07-18 09:26:24,942 - __main__ - INFO - started mining
2021-07-18 09:26:24,942 - __main__ - INFO - reading transactional data
2021-07-18 09:26:25,212 - __main__ - INFO - transactions size: 8368681
2021-07-18 09:26:25,212 - __main__ - INFO - First level mining
2021-07-18 09:26:27,778 - __main__ - INFO - Got first level patterns : 20  writing to file
2021-07-18 09:26:27,779 - __main__ - INFO - Generating second level candidateset
2021-07-18 09:26:27,973 - __main__ - INFO - saving 2 level patterns
2021-07-18 09:26:27,973 - __main__ - INFO - found 45 patterns
2021-07-18 09:26:27,973 - __main__ - INFO - computing patterns for level : 3
2021-07-18 09:26:28,267 - __main__ - INFO - saving 3 level patterns
2021-07-18 09:26:28,267 - __main__ - INFO - found 0 patterns
2021-07-18 09:26:28,267 - __main__ - INFO - computing patterns for level : 4
2021-07-18 09:26:28,378 - __main__ - INFO - saving 4 level patterns
2021-07-18 09:26:28,424 - __main__ - INFO - total time taken: 3.4828147888183594
2021-07-18 09:26:28,425 - root - INFO - broadcast size:2964751
shuffle read:1871
shuffle write:74
2021-07-23 20:20:50,231 - __main__ - INFO - Got the following arguments: ['our_newtest.py', '0.03', '1', '0.2', '8', '../CMineMR-Mapreduce-algorithm-to-extract-coverage-patterns-master/dataset/synthetic.txt', 'varying_mincs_mushroom_0.2_ultrmaxprodummy']
2021-07-23 20:20:55,828 - __main__ - INFO - started mining
2021-07-23 20:20:55,829 - __main__ - INFO - reading transactional data
2021-07-23 20:20:56,019 - __main__ - INFO - First level mining
2021-07-23 20:20:59,256 - __main__ - INFO - Got first level patterns : 60  writing to file
2021-07-23 20:20:59,268 - __main__ - INFO - Generating second level candidateset
2021-07-23 20:20:59,691 - __main__ - INFO - saving 2 level patterns
2021-07-23 20:20:59,691 - __main__ - INFO - found 1756 patterns
2021-07-23 20:20:59,691 - __main__ - INFO - computing patterns for level : 3
2021-07-23 20:21:02,941 - __main__ - INFO - saving 3 level patterns
2021-07-23 20:21:02,942 - __main__ - INFO - found 32371 patterns
2021-07-23 20:21:02,942 - __main__ - INFO - computing patterns for level : 4
2021-07-23 20:21:35,866 - __main__ - INFO - saving 4 level patterns
2021-07-23 20:21:35,875 - __main__ - INFO - found 399687 patterns
2021-07-23 20:21:35,875 - __main__ - INFO - computing patterns for level : 5
2021-07-23 20:26:22,270 - __main__ - INFO - saving 5 level patterns
2021-07-23 20:26:22,346 - __main__ - INFO - found 3216448 patterns
2021-07-23 20:26:22,346 - __main__ - INFO - computing patterns for level : 6
2021-07-23 20:34:10,846 - py4j.java_gateway - INFO - Error while receiving.
Traceback (most recent call last):
  File "/home/preetham_sathineni/anaconda2/envs/py37/lib/python3.7/site-packages/py4j/java_gateway.py", line 1200, in send_command
    answer = smart_decode(self.stream.readline()[:-1])
  File "/home/preetham_sathineni/anaconda2/envs/py37/lib/python3.7/socket.py", line 589, in readinto
    return self._sock.recv_into(b)
ConnectionResetError: [Errno 104] Connection reset by peer
2021-07-23 20:34:10,866 - root - ERROR - Exception while sending command.
Traceback (most recent call last):
  File "/home/preetham_sathineni/anaconda2/envs/py37/lib/python3.7/site-packages/py4j/java_gateway.py", line 1200, in send_command
    answer = smart_decode(self.stream.readline()[:-1])
  File "/home/preetham_sathineni/anaconda2/envs/py37/lib/python3.7/socket.py", line 589, in readinto
    return self._sock.recv_into(b)
ConnectionResetError: [Errno 104] Connection reset by peer

During handling of the above exception, another exception occurred:

Traceback (most recent call last):
  File "/home/preetham_sathineni/anaconda2/envs/py37/lib/python3.7/site-packages/py4j/java_gateway.py", line 1033, in send_command
    response = connection.send_command(command)
  File "/home/preetham_sathineni/anaconda2/envs/py37/lib/python3.7/site-packages/py4j/java_gateway.py", line 1212, in send_command
    "Error while receiving", e, proto.ERROR_ON_RECEIVE)
py4j.protocol.Py4JNetworkError: Error while receiving
2021-07-23 20:34:10,867 - py4j.java_gateway - ERROR - An error occurred while trying to connect to the Java server (127.0.0.1:40989)
Traceback (most recent call last):
  File "/home/preetham_sathineni/anaconda2/envs/py37/lib/python3.7/site-packages/py4j/java_gateway.py", line 977, in _get_connection
    connection = self.deque.pop()
IndexError: pop from an empty deque

During handling of the above exception, another exception occurred:

Traceback (most recent call last):
  File "/home/preetham_sathineni/anaconda2/envs/py37/lib/python3.7/site-packages/py4j/java_gateway.py", line 1115, in start
    self.socket.connect((self.address, self.port))
ConnectionRefusedError: [Errno 111] Connection refused
2021-07-23 20:34:10,867 - py4j.java_gateway - ERROR - An error occurred while trying to connect to the Java server (127.0.0.1:40989)
Traceback (most recent call last):
  File "/home/preetham_sathineni/anaconda2/envs/py37/lib/python3.7/site-packages/py4j/java_gateway.py", line 977, in _get_connection
    connection = self.deque.pop()
IndexError: pop from an empty deque

During handling of the above exception, another exception occurred:

Traceback (most recent call last):
  File "/home/preetham_sathineni/anaconda2/envs/py37/lib/python3.7/site-packages/py4j/java_gateway.py", line 1115, in start
    self.socket.connect((self.address, self.port))
ConnectionRefusedError: [Errno 111] Connection refused
2021-07-23 20:34:10,867 - py4j.java_gateway - ERROR - An error occurred while trying to connect to the Java server (127.0.0.1:40989)
Traceback (most recent call last):
  File "/home/preetham_sathineni/anaconda2/envs/py37/lib/python3.7/site-packages/py4j/java_gateway.py", line 977, in _get_connection
    connection = self.deque.pop()
IndexError: pop from an empty deque

During handling of the above exception, another exception occurred:

Traceback (most recent call last):
  File "/home/preetham_sathineni/anaconda2/envs/py37/lib/python3.7/site-packages/py4j/java_gateway.py", line 1115, in start
    self.socket.connect((self.address, self.port))
ConnectionRefusedError: [Errno 111] Connection refused
2021-07-23 20:34:10,868 - py4j.java_gateway - ERROR - An error occurred while trying to connect to the Java server (127.0.0.1:40989)
Traceback (most recent call last):
  File "/home/preetham_sathineni/anaconda2/envs/py37/lib/python3.7/site-packages/py4j/java_gateway.py", line 977, in _get_connection
    connection = self.deque.pop()
IndexError: pop from an empty deque

During handling of the above exception, another exception occurred:

Traceback (most recent call last):
  File "/home/preetham_sathineni/anaconda2/envs/py37/lib/python3.7/site-packages/py4j/java_gateway.py", line 1115, in start
    self.socket.connect((self.address, self.port))
ConnectionRefusedError: [Errno 111] Connection refused
2021-07-23 20:34:10,868 - py4j.java_gateway - ERROR - An error occurred while trying to connect to the Java server (127.0.0.1:40989)
Traceback (most recent call last):
  File "/home/preetham_sathineni/anaconda2/envs/py37/lib/python3.7/site-packages/py4j/java_gateway.py", line 977, in _get_connection
    connection = self.deque.pop()
IndexError: pop from an empty deque

During handling of the above exception, another exception occurred:

Traceback (most recent call last):
  File "/home/preetham_sathineni/anaconda2/envs/py37/lib/python3.7/site-packages/py4j/java_gateway.py", line 1115, in start
    self.socket.connect((self.address, self.port))
ConnectionRefusedError: [Errno 111] Connection refused
2021-07-23 20:34:10,868 - py4j.java_gateway - ERROR - An error occurred while trying to connect to the Java server (127.0.0.1:40989)
Traceback (most recent call last):
  File "/home/preetham_sathineni/anaconda2/envs/py37/lib/python3.7/site-packages/py4j/java_gateway.py", line 977, in _get_connection
    connection = self.deque.pop()
IndexError: pop from an empty deque

During handling of the above exception, another exception occurred:

Traceback (most recent call last):
  File "/home/preetham_sathineni/anaconda2/envs/py37/lib/python3.7/site-packages/py4j/java_gateway.py", line 1115, in start
    self.socket.connect((self.address, self.port))
ConnectionRefusedError: [Errno 111] Connection refused
2021-07-23 20:34:11,464 - py4j.java_gateway - ERROR - An error occurred while trying to connect to the Java server (127.0.0.1:40989)
Traceback (most recent call last):
  File "/home/preetham_sathineni/anaconda2/envs/py37/lib/python3.7/site-packages/py4j/java_gateway.py", line 977, in _get_connection
    connection = self.deque.pop()
IndexError: pop from an empty deque

During handling of the above exception, another exception occurred:

Traceback (most recent call last):
  File "/home/preetham_sathineni/anaconda2/envs/py37/lib/python3.7/site-packages/py4j/java_gateway.py", line 1115, in start
    self.socket.connect((self.address, self.port))
ConnectionRefusedError: [Errno 111] Connection refused
2021-07-23 20:34:11,465 - py4j.java_gateway - ERROR - An error occurred while trying to connect to the Java server (127.0.0.1:40989)
Traceback (most recent call last):
  File "/home/preetham_sathineni/anaconda2/envs/py37/lib/python3.7/site-packages/py4j/java_gateway.py", line 977, in _get_connection
    connection = self.deque.pop()
IndexError: pop from an empty deque

During handling of the above exception, another exception occurred:

Traceback (most recent call last):
  File "/home/preetham_sathineni/anaconda2/envs/py37/lib/python3.7/site-packages/py4j/java_gateway.py", line 1115, in start
    self.socket.connect((self.address, self.port))
ConnectionRefusedError: [Errno 111] Connection refused
2021-07-23 20:34:11,465 - py4j.java_gateway - ERROR - An error occurred while trying to connect to the Java server (127.0.0.1:40989)
Traceback (most recent call last):
  File "/home/preetham_sathineni/anaconda2/envs/py37/lib/python3.7/site-packages/py4j/java_gateway.py", line 977, in _get_connection
    connection = self.deque.pop()
IndexError: pop from an empty deque

During handling of the above exception, another exception occurred:

Traceback (most recent call last):
  File "/home/preetham_sathineni/anaconda2/envs/py37/lib/python3.7/site-packages/py4j/java_gateway.py", line 1115, in start
    self.socket.connect((self.address, self.port))
ConnectionRefusedError: [Errno 111] Connection refused
2021-07-23 20:34:11,465 - py4j.java_gateway - ERROR - An error occurred while trying to connect to the Java server (127.0.0.1:40989)
Traceback (most recent call last):
  File "/home/preetham_sathineni/anaconda2/envs/py37/lib/python3.7/site-packages/py4j/java_gateway.py", line 977, in _get_connection
    connection = self.deque.pop()
IndexError: pop from an empty deque

During handling of the above exception, another exception occurred:

Traceback (most recent call last):
  File "/home/preetham_sathineni/anaconda2/envs/py37/lib/python3.7/site-packages/py4j/java_gateway.py", line 1115, in start
    self.socket.connect((self.address, self.port))
ConnectionRefusedError: [Errno 111] Connection refused
2021-07-23 20:34:11,465 - py4j.java_gateway - ERROR - An error occurred while trying to connect to the Java server (127.0.0.1:40989)
Traceback (most recent call last):
  File "/home/preetham_sathineni/anaconda2/envs/py37/lib/python3.7/site-packages/py4j/java_gateway.py", line 977, in _get_connection
    connection = self.deque.pop()
IndexError: pop from an empty deque

During handling of the above exception, another exception occurred:

Traceback (most recent call last):
  File "/home/preetham_sathineni/anaconda2/envs/py37/lib/python3.7/site-packages/py4j/java_gateway.py", line 1115, in start
    self.socket.connect((self.address, self.port))
ConnectionRefusedError: [Errno 111] Connection refused
2021-07-23 20:34:11,466 - py4j.java_gateway - ERROR - An error occurred while trying to connect to the Java server (127.0.0.1:40989)
Traceback (most recent call last):
  File "/home/preetham_sathineni/anaconda2/envs/py37/lib/python3.7/site-packages/py4j/java_gateway.py", line 977, in _get_connection
    connection = self.deque.pop()
IndexError: pop from an empty deque

During handling of the above exception, another exception occurred:

Traceback (most recent call last):
  File "/home/preetham_sathineni/anaconda2/envs/py37/lib/python3.7/site-packages/py4j/java_gateway.py", line 1115, in start
    self.socket.connect((self.address, self.port))
ConnectionRefusedError: [Errno 111] Connection refused
2021-07-23 20:34:11,466 - py4j.java_gateway - ERROR - An error occurred while trying to connect to the Java server (127.0.0.1:40989)
Traceback (most recent call last):
  File "/home/preetham_sathineni/anaconda2/envs/py37/lib/python3.7/site-packages/py4j/java_gateway.py", line 977, in _get_connection
    connection = self.deque.pop()
IndexError: pop from an empty deque

During handling of the above exception, another exception occurred:

Traceback (most recent call last):
  File "/home/preetham_sathineni/anaconda2/envs/py37/lib/python3.7/site-packages/py4j/java_gateway.py", line 1115, in start
    self.socket.connect((self.address, self.port))
ConnectionRefusedError: [Errno 111] Connection refused
2021-07-23 20:34:11,466 - py4j.java_gateway - ERROR - An error occurred while trying to connect to the Java server (127.0.0.1:40989)
Traceback (most recent call last):
  File "/home/preetham_sathineni/anaconda2/envs/py37/lib/python3.7/site-packages/py4j/java_gateway.py", line 977, in _get_connection
    connection = self.deque.pop()
IndexError: pop from an empty deque

During handling of the above exception, another exception occurred:

Traceback (most recent call last):
  File "/home/preetham_sathineni/anaconda2/envs/py37/lib/python3.7/site-packages/py4j/java_gateway.py", line 1115, in start
    self.socket.connect((self.address, self.port))
ConnectionRefusedError: [Errno 111] Connection refused
2021-07-23 20:34:11,466 - py4j.java_gateway - ERROR - An error occurred while trying to connect to the Java server (127.0.0.1:40989)
Traceback (most recent call last):
  File "/home/preetham_sathineni/anaconda2/envs/py37/lib/python3.7/site-packages/py4j/java_gateway.py", line 977, in _get_connection
    connection = self.deque.pop()
IndexError: pop from an empty deque

During handling of the above exception, another exception occurred:

Traceback (most recent call last):
  File "/home/preetham_sathineni/anaconda2/envs/py37/lib/python3.7/site-packages/py4j/java_gateway.py", line 1115, in start
    self.socket.connect((self.address, self.port))
ConnectionRefusedError: [Errno 111] Connection refused
2021-07-23 20:34:11,466 - py4j.java_gateway - ERROR - An error occurred while trying to connect to the Java server (127.0.0.1:40989)
Traceback (most recent call last):
  File "/home/preetham_sathineni/anaconda2/envs/py37/lib/python3.7/site-packages/py4j/java_gateway.py", line 977, in _get_connection
    connection = self.deque.pop()
IndexError: pop from an empty deque

During handling of the above exception, another exception occurred:

Traceback (most recent call last):
  File "/home/preetham_sathineni/anaconda2/envs/py37/lib/python3.7/site-packages/py4j/java_gateway.py", line 1115, in start
    self.socket.connect((self.address, self.port))
ConnectionRefusedError: [Errno 111] Connection refused
2021-07-23 20:34:11,467 - py4j.java_gateway - ERROR - An error occurred while trying to connect to the Java server (127.0.0.1:40989)
Traceback (most recent call last):
  File "/home/preetham_sathineni/anaconda2/envs/py37/lib/python3.7/site-packages/py4j/java_gateway.py", line 977, in _get_connection
    connection = self.deque.pop()
IndexError: pop from an empty deque

During handling of the above exception, another exception occurred:

Traceback (most recent call last):
  File "/home/preetham_sathineni/anaconda2/envs/py37/lib/python3.7/site-packages/py4j/java_gateway.py", line 1115, in start
    self.socket.connect((self.address, self.port))
ConnectionRefusedError: [Errno 111] Connection refused
2021-07-23 20:34:11,467 - py4j.java_gateway - ERROR - An error occurred while trying to connect to the Java server (127.0.0.1:40989)
Traceback (most recent call last):
  File "/home/preetham_sathineni/anaconda2/envs/py37/lib/python3.7/site-packages/py4j/java_gateway.py", line 977, in _get_connection
    connection = self.deque.pop()
IndexError: pop from an empty deque

During handling of the above exception, another exception occurred:

Traceback (most recent call last):
  File "/home/preetham_sathineni/anaconda2/envs/py37/lib/python3.7/site-packages/py4j/java_gateway.py", line 1115, in start
    self.socket.connect((self.address, self.port))
ConnectionRefusedError: [Errno 111] Connection refused
2021-07-23 20:34:11,467 - py4j.java_gateway - ERROR - An error occurred while trying to connect to the Java server (127.0.0.1:40989)
Traceback (most recent call last):
  File "/home/preetham_sathineni/anaconda2/envs/py37/lib/python3.7/site-packages/py4j/java_gateway.py", line 977, in _get_connection
    connection = self.deque.pop()
IndexError: pop from an empty deque

During handling of the above exception, another exception occurred:

Traceback (most recent call last):
  File "/home/preetham_sathineni/anaconda2/envs/py37/lib/python3.7/site-packages/py4j/java_gateway.py", line 1115, in start
    self.socket.connect((self.address, self.port))
ConnectionRefusedError: [Errno 111] Connection refused
2021-07-23 20:34:11,467 - py4j.java_gateway - ERROR - An error occurred while trying to connect to the Java server (127.0.0.1:40989)
Traceback (most recent call last):
  File "/home/preetham_sathineni/anaconda2/envs/py37/lib/python3.7/site-packages/py4j/java_gateway.py", line 977, in _get_connection
    connection = self.deque.pop()
IndexError: pop from an empty deque

During handling of the above exception, another exception occurred:

Traceback (most recent call last):
  File "/home/preetham_sathineni/anaconda2/envs/py37/lib/python3.7/site-packages/py4j/java_gateway.py", line 1115, in start
    self.socket.connect((self.address, self.port))
ConnectionRefusedError: [Errno 111] Connection refused
2021-07-23 20:34:11,468 - py4j.java_gateway - ERROR - An error occurred while trying to connect to the Java server (127.0.0.1:40989)
Traceback (most recent call last):
  File "/home/preetham_sathineni/anaconda2/envs/py37/lib/python3.7/site-packages/py4j/java_gateway.py", line 977, in _get_connection
    connection = self.deque.pop()
IndexError: pop from an empty deque

During handling of the above exception, another exception occurred:

Traceback (most recent call last):
  File "/home/preetham_sathineni/anaconda2/envs/py37/lib/python3.7/site-packages/py4j/java_gateway.py", line 1115, in start
    self.socket.connect((self.address, self.port))
ConnectionRefusedError: [Errno 111] Connection refused
2021-07-23 20:34:11,468 - py4j.java_gateway - ERROR - An error occurred while trying to connect to the Java server (127.0.0.1:40989)
Traceback (most recent call last):
  File "/home/preetham_sathineni/anaconda2/envs/py37/lib/python3.7/site-packages/py4j/java_gateway.py", line 977, in _get_connection
    connection = self.deque.pop()
IndexError: pop from an empty deque

During handling of the above exception, another exception occurred:

Traceback (most recent call last):
  File "/home/preetham_sathineni/anaconda2/envs/py37/lib/python3.7/site-packages/py4j/java_gateway.py", line 1115, in start
    self.socket.connect((self.address, self.port))
ConnectionRefusedError: [Errno 111] Connection refused
2021-07-23 20:34:11,468 - py4j.java_gateway - ERROR - An error occurred while trying to connect to the Java server (127.0.0.1:40989)
Traceback (most recent call last):
  File "/home/preetham_sathineni/anaconda2/envs/py37/lib/python3.7/site-packages/py4j/java_gateway.py", line 977, in _get_connection
    connection = self.deque.pop()
IndexError: pop from an empty deque

During handling of the above exception, another exception occurred:

Traceback (most recent call last):
  File "/home/preetham_sathineni/anaconda2/envs/py37/lib/python3.7/site-packages/py4j/java_gateway.py", line 1115, in start
    self.socket.connect((self.address, self.port))
ConnectionRefusedError: [Errno 111] Connection refused
2021-07-25 00:31:48,942 - __main__ - INFO - Got the following arguments: ['our_newtest.py', '0.04', '1', '0.2', '16', '../CMineMR-Mapreduce-algorithm-to-extract-coverage-patterns-master/dataset/mushroom.txt', 'varying_mincs_mushroom_0.2_ultrmaxprodummy']
2021-07-25 00:31:54,771 - __main__ - INFO - started mining
2021-07-25 00:31:54,772 - __main__ - INFO - reading transactional data
2021-07-25 00:31:54,803 - __main__ - INFO - First level mining
2021-07-25 00:31:56,740 - __main__ - INFO - Got first level patterns : 79  writing to file
2021-07-25 00:31:56,741 - __main__ - INFO - Generating second level candidateset
2021-07-25 00:31:57,024 - __main__ - INFO - saving 2 level patterns
2021-07-25 00:31:57,024 - __main__ - INFO - found 1150 patterns
2021-07-25 00:31:57,024 - __main__ - INFO - computing patterns for level : 3
2021-07-25 00:31:57,276 - __main__ - INFO - saving 3 level patterns
2021-07-25 00:31:57,277 - __main__ - INFO - found 6393 patterns
2021-07-25 00:31:57,277 - __main__ - INFO - computing patterns for level : 4
2021-07-25 00:31:57,635 - __main__ - INFO - saving 4 level patterns
2021-07-25 00:31:57,636 - __main__ - INFO - found 16903 patterns
2021-07-25 00:31:57,636 - __main__ - INFO - computing patterns for level : 5
2021-07-25 00:31:58,140 - __main__ - INFO - saving 5 level patterns
2021-07-25 00:31:58,143 - __main__ - INFO - found 24711 patterns
2021-07-25 00:31:58,143 - __main__ - INFO - computing patterns for level : 6
2021-07-25 00:31:58,890 - __main__ - INFO - saving 6 level patterns
2021-07-25 00:31:58,893 - __main__ - INFO - found 21588 patterns
2021-07-25 00:31:58,894 - __main__ - INFO - computing patterns for level : 7
2021-07-25 00:31:59,525 - __main__ - INFO - saving 7 level patterns
2021-07-25 00:31:59,528 - __main__ - INFO - found 11632 patterns
2021-07-25 00:31:59,528 - __main__ - INFO - computing patterns for level : 8
2021-07-25 00:31:59,858 - __main__ - INFO - saving 8 level patterns
2021-07-25 00:31:59,859 - __main__ - INFO - found 3816 patterns
2021-07-25 00:31:59,859 - __main__ - INFO - computing patterns for level : 9
2021-07-25 00:32:00,057 - __main__ - INFO - saving 9 level patterns
2021-07-25 00:32:00,057 - __main__ - INFO - found 697 patterns
2021-07-25 00:32:00,058 - __main__ - INFO - computing patterns for level : 10
2021-07-25 00:32:00,150 - __main__ - INFO - saving 10 level patterns
2021-07-25 00:32:00,150 - __main__ - INFO - found 54 patterns
2021-07-25 00:32:00,150 - __main__ - INFO - computing patterns for level : 11
2021-07-25 00:32:00,257 - __main__ - INFO - saving 11 level patterns
2021-07-25 00:32:00,258 - __main__ - INFO - found 0 patterns
2021-07-25 00:32:00,258 - __main__ - INFO - computing patterns for level : 12
2021-07-25 00:32:00,368 - __main__ - INFO - saving 12 level patterns
2021-07-25 00:32:00,378 - __main__ - INFO - total time taken: 5.606310129165649
2021-07-25 00:32:00,379 - root - INFO - broadcast size:0
shuffle read:0
shuffle write:0
