2021-07-26 00:16:08,937 - __main__ - INFO - Got the following arguments: ['our_newtest.py', '0.04', '1', '0.45', '16', '../CMineMR-Mapreduce-algorithm-to-extract-coverage-patterns-master/dataset/synthetic.txt', 'varying_mincs_synthetic_0.45_ultrmaxprodummy']
2021-07-26 00:16:14,444 - __main__ - INFO - started mining
2021-07-26 00:16:14,444 - __main__ - INFO - reading transactional data
2021-07-26 00:16:14,617 - __main__ - INFO - First level mining
2021-07-26 00:16:17,594 - __main__ - INFO - Got first level patterns : 26  writing to file
2021-07-26 00:16:17,596 - __main__ - INFO - Generating second level candidateset
2021-07-26 00:16:17,766 - __main__ - INFO - saving 2 level patterns
2021-07-26 00:16:17,766 - __main__ - INFO - found 325 patterns
2021-07-26 00:16:17,766 - __main__ - INFO - computing patterns for level : 3
2021-07-26 00:16:18,298 - __main__ - INFO - saving 3 level patterns
2021-07-26 00:16:18,298 - __main__ - INFO - found 2600 patterns
2021-07-26 00:16:18,298 - __main__ - INFO - computing patterns for level : 4
2021-07-26 00:16:19,621 - __main__ - INFO - saving 4 level patterns
2021-07-26 00:16:19,622 - __main__ - INFO - found 14950 patterns
2021-07-26 00:16:19,622 - __main__ - INFO - computing patterns for level : 5
2021-07-26 00:16:25,240 - __main__ - INFO - saving 5 level patterns
2021-07-26 00:16:25,242 - __main__ - INFO - found 65756 patterns
2021-07-26 00:16:25,242 - __main__ - INFO - computing patterns for level : 6
2021-07-26 00:16:48,274 - __main__ - INFO - saving 6 level patterns
2021-07-26 00:16:48,283 - __main__ - INFO - found 229334 patterns
2021-07-26 00:16:48,283 - __main__ - INFO - computing patterns for level : 7
2021-07-26 00:18:01,573 - __main__ - INFO - saving 7 level patterns
2021-07-26 00:18:01,607 - __main__ - INFO - found 643538 patterns
2021-07-26 00:18:01,607 - __main__ - INFO - computing patterns for level : 8
2021-07-26 00:21:26,328 - __main__ - INFO - saving 8 level patterns
2021-07-26 00:21:26,422 - __main__ - INFO - found 1450630 patterns
2021-07-26 00:21:26,422 - __main__ - INFO - computing patterns for level : 9
2021-07-26 00:29:51,930 - __main__ - INFO - saving 9 level patterns
2021-07-26 00:29:52,128 - __main__ - INFO - found 2589875 patterns
2021-07-26 00:29:52,128 - __main__ - INFO - computing patterns for level : 10
2021-07-26 00:41:01,947 - py4j.java_gateway - INFO - Error while receiving.
Traceback (most recent call last):
  File "/home/preetham_sathineni/anaconda2/envs/py37/lib/python3.7/site-packages/py4j/java_gateway.py", line 1207, in send_command
    raise Py4JNetworkError("Answer from Java side is empty")
py4j.protocol.Py4JNetworkError: Answer from Java side is empty
2021-07-26 00:41:01,962 - root - ERROR - Exception while sending command.
Traceback (most recent call last):
  File "/home/preetham_sathineni/anaconda2/envs/py37/lib/python3.7/site-packages/py4j/java_gateway.py", line 1207, in send_command
    raise Py4JNetworkError("Answer from Java side is empty")
py4j.protocol.Py4JNetworkError: Answer from Java side is empty

During handling of the above exception, another exception occurred:

Traceback (most recent call last):
  File "/home/preetham_sathineni/anaconda2/envs/py37/lib/python3.7/site-packages/py4j/java_gateway.py", line 1033, in send_command
    response = connection.send_command(command)
  File "/home/preetham_sathineni/anaconda2/envs/py37/lib/python3.7/site-packages/py4j/java_gateway.py", line 1212, in send_command
    "Error while receiving", e, proto.ERROR_ON_RECEIVE)
py4j.protocol.Py4JNetworkError: Error while receiving
2021-07-26 00:41:01,962 - py4j.java_gateway - ERROR - An error occurred while trying to connect to the Java server (127.0.0.1:35157)
Traceback (most recent call last):
  File "/home/preetham_sathineni/anaconda2/envs/py37/lib/python3.7/site-packages/py4j/java_gateway.py", line 977, in _get_connection
    connection = self.deque.pop()
IndexError: pop from an empty deque

During handling of the above exception, another exception occurred:

Traceback (most recent call last):
  File "/home/preetham_sathineni/anaconda2/envs/py37/lib/python3.7/site-packages/py4j/java_gateway.py", line 1115, in start
    self.socket.connect((self.address, self.port))
ConnectionRefusedError: [Errno 111] Connection refused
2021-07-26 00:41:01,963 - py4j.java_gateway - ERROR - An error occurred while trying to connect to the Java server (127.0.0.1:35157)
Traceback (most recent call last):
  File "/home/preetham_sathineni/anaconda2/envs/py37/lib/python3.7/site-packages/py4j/java_gateway.py", line 977, in _get_connection
    connection = self.deque.pop()
IndexError: pop from an empty deque

During handling of the above exception, another exception occurred:

Traceback (most recent call last):
  File "/home/preetham_sathineni/anaconda2/envs/py37/lib/python3.7/site-packages/py4j/java_gateway.py", line 1115, in start
    self.socket.connect((self.address, self.port))
ConnectionRefusedError: [Errno 111] Connection refused
2021-07-26 00:41:01,963 - py4j.java_gateway - ERROR - An error occurred while trying to connect to the Java server (127.0.0.1:35157)
Traceback (most recent call last):
  File "/home/preetham_sathineni/anaconda2/envs/py37/lib/python3.7/site-packages/py4j/java_gateway.py", line 977, in _get_connection
    connection = self.deque.pop()
IndexError: pop from an empty deque

During handling of the above exception, another exception occurred:

Traceback (most recent call last):
  File "/home/preetham_sathineni/anaconda2/envs/py37/lib/python3.7/site-packages/py4j/java_gateway.py", line 1115, in start
    self.socket.connect((self.address, self.port))
ConnectionRefusedError: [Errno 111] Connection refused
2021-07-26 00:41:01,963 - py4j.java_gateway - ERROR - An error occurred while trying to connect to the Java server (127.0.0.1:35157)
Traceback (most recent call last):
  File "/home/preetham_sathineni/anaconda2/envs/py37/lib/python3.7/site-packages/py4j/java_gateway.py", line 977, in _get_connection
    connection = self.deque.pop()
IndexError: pop from an empty deque

During handling of the above exception, another exception occurred:

Traceback (most recent call last):
  File "/home/preetham_sathineni/anaconda2/envs/py37/lib/python3.7/site-packages/py4j/java_gateway.py", line 1115, in start
    self.socket.connect((self.address, self.port))
ConnectionRefusedError: [Errno 111] Connection refused
2021-07-26 00:41:01,964 - py4j.java_gateway - ERROR - An error occurred while trying to connect to the Java server (127.0.0.1:35157)
Traceback (most recent call last):
  File "/home/preetham_sathineni/anaconda2/envs/py37/lib/python3.7/site-packages/py4j/java_gateway.py", line 977, in _get_connection
    connection = self.deque.pop()
IndexError: pop from an empty deque

During handling of the above exception, another exception occurred:

Traceback (most recent call last):
  File "/home/preetham_sathineni/anaconda2/envs/py37/lib/python3.7/site-packages/py4j/java_gateway.py", line 1115, in start
    self.socket.connect((self.address, self.port))
ConnectionRefusedError: [Errno 111] Connection refused
2021-07-26 00:41:01,964 - py4j.java_gateway - ERROR - An error occurred while trying to connect to the Java server (127.0.0.1:35157)
Traceback (most recent call last):
  File "/home/preetham_sathineni/anaconda2/envs/py37/lib/python3.7/site-packages/py4j/java_gateway.py", line 977, in _get_connection
    connection = self.deque.pop()
IndexError: pop from an empty deque

During handling of the above exception, another exception occurred:

Traceback (most recent call last):
  File "/home/preetham_sathineni/anaconda2/envs/py37/lib/python3.7/site-packages/py4j/java_gateway.py", line 1115, in start
    self.socket.connect((self.address, self.port))
ConnectionRefusedError: [Errno 111] Connection refused
2021-07-26 00:41:02,514 - py4j.java_gateway - ERROR - An error occurred while trying to connect to the Java server (127.0.0.1:35157)
Traceback (most recent call last):
  File "/home/preetham_sathineni/anaconda2/envs/py37/lib/python3.7/site-packages/py4j/java_gateway.py", line 977, in _get_connection
    connection = self.deque.pop()
IndexError: pop from an empty deque

During handling of the above exception, another exception occurred:

Traceback (most recent call last):
  File "/home/preetham_sathineni/anaconda2/envs/py37/lib/python3.7/site-packages/py4j/java_gateway.py", line 1115, in start
    self.socket.connect((self.address, self.port))
ConnectionRefusedError: [Errno 111] Connection refused
2021-07-26 00:41:02,514 - py4j.java_gateway - ERROR - An error occurred while trying to connect to the Java server (127.0.0.1:35157)
Traceback (most recent call last):
  File "/home/preetham_sathineni/anaconda2/envs/py37/lib/python3.7/site-packages/py4j/java_gateway.py", line 977, in _get_connection
    connection = self.deque.pop()
IndexError: pop from an empty deque

During handling of the above exception, another exception occurred:

Traceback (most recent call last):
  File "/home/preetham_sathineni/anaconda2/envs/py37/lib/python3.7/site-packages/py4j/java_gateway.py", line 1115, in start
    self.socket.connect((self.address, self.port))
ConnectionRefusedError: [Errno 111] Connection refused
2021-07-26 00:41:02,514 - py4j.java_gateway - ERROR - An error occurred while trying to connect to the Java server (127.0.0.1:35157)
Traceback (most recent call last):
  File "/home/preetham_sathineni/anaconda2/envs/py37/lib/python3.7/site-packages/py4j/java_gateway.py", line 977, in _get_connection
    connection = self.deque.pop()
IndexError: pop from an empty deque

During handling of the above exception, another exception occurred:

Traceback (most recent call last):
  File "/home/preetham_sathineni/anaconda2/envs/py37/lib/python3.7/site-packages/py4j/java_gateway.py", line 1115, in start
    self.socket.connect((self.address, self.port))
ConnectionRefusedError: [Errno 111] Connection refused
2021-07-26 00:41:02,514 - py4j.java_gateway - ERROR - An error occurred while trying to connect to the Java server (127.0.0.1:35157)
Traceback (most recent call last):
  File "/home/preetham_sathineni/anaconda2/envs/py37/lib/python3.7/site-packages/py4j/java_gateway.py", line 977, in _get_connection
    connection = self.deque.pop()
IndexError: pop from an empty deque

During handling of the above exception, another exception occurred:

Traceback (most recent call last):
  File "/home/preetham_sathineni/anaconda2/envs/py37/lib/python3.7/site-packages/py4j/java_gateway.py", line 1115, in start
    self.socket.connect((self.address, self.port))
ConnectionRefusedError: [Errno 111] Connection refused
2021-07-26 00:41:02,515 - py4j.java_gateway - ERROR - An error occurred while trying to connect to the Java server (127.0.0.1:35157)
Traceback (most recent call last):
  File "/home/preetham_sathineni/anaconda2/envs/py37/lib/python3.7/site-packages/py4j/java_gateway.py", line 977, in _get_connection
    connection = self.deque.pop()
IndexError: pop from an empty deque

During handling of the above exception, another exception occurred:

Traceback (most recent call last):
  File "/home/preetham_sathineni/anaconda2/envs/py37/lib/python3.7/site-packages/py4j/java_gateway.py", line 1115, in start
    self.socket.connect((self.address, self.port))
ConnectionRefusedError: [Errno 111] Connection refused
2021-07-26 00:41:02,515 - py4j.java_gateway - ERROR - An error occurred while trying to connect to the Java server (127.0.0.1:35157)
Traceback (most recent call last):
  File "/home/preetham_sathineni/anaconda2/envs/py37/lib/python3.7/site-packages/py4j/java_gateway.py", line 977, in _get_connection
    connection = self.deque.pop()
IndexError: pop from an empty deque

During handling of the above exception, another exception occurred:

Traceback (most recent call last):
  File "/home/preetham_sathineni/anaconda2/envs/py37/lib/python3.7/site-packages/py4j/java_gateway.py", line 1115, in start
    self.socket.connect((self.address, self.port))
ConnectionRefusedError: [Errno 111] Connection refused
2021-07-26 00:41:02,515 - py4j.java_gateway - ERROR - An error occurred while trying to connect to the Java server (127.0.0.1:35157)
Traceback (most recent call last):
  File "/home/preetham_sathineni/anaconda2/envs/py37/lib/python3.7/site-packages/py4j/java_gateway.py", line 977, in _get_connection
    connection = self.deque.pop()
IndexError: pop from an empty deque

During handling of the above exception, another exception occurred:

Traceback (most recent call last):
  File "/home/preetham_sathineni/anaconda2/envs/py37/lib/python3.7/site-packages/py4j/java_gateway.py", line 1115, in start
    self.socket.connect((self.address, self.port))
ConnectionRefusedError: [Errno 111] Connection refused
2021-07-26 00:41:02,515 - py4j.java_gateway - ERROR - An error occurred while trying to connect to the Java server (127.0.0.1:35157)
Traceback (most recent call last):
  File "/home/preetham_sathineni/anaconda2/envs/py37/lib/python3.7/site-packages/py4j/java_gateway.py", line 977, in _get_connection
    connection = self.deque.pop()
IndexError: pop from an empty deque

During handling of the above exception, another exception occurred:

Traceback (most recent call last):
  File "/home/preetham_sathineni/anaconda2/envs/py37/lib/python3.7/site-packages/py4j/java_gateway.py", line 1115, in start
    self.socket.connect((self.address, self.port))
ConnectionRefusedError: [Errno 111] Connection refused
2021-07-26 00:41:02,516 - py4j.java_gateway - ERROR - An error occurred while trying to connect to the Java server (127.0.0.1:35157)
Traceback (most recent call last):
  File "/home/preetham_sathineni/anaconda2/envs/py37/lib/python3.7/site-packages/py4j/java_gateway.py", line 977, in _get_connection
    connection = self.deque.pop()
IndexError: pop from an empty deque

During handling of the above exception, another exception occurred:

Traceback (most recent call last):
  File "/home/preetham_sathineni/anaconda2/envs/py37/lib/python3.7/site-packages/py4j/java_gateway.py", line 1115, in start
    self.socket.connect((self.address, self.port))
ConnectionRefusedError: [Errno 111] Connection refused
2021-07-26 00:41:02,516 - py4j.java_gateway - ERROR - An error occurred while trying to connect to the Java server (127.0.0.1:35157)
Traceback (most recent call last):
  File "/home/preetham_sathineni/anaconda2/envs/py37/lib/python3.7/site-packages/py4j/java_gateway.py", line 977, in _get_connection
    connection = self.deque.pop()
IndexError: pop from an empty deque

During handling of the above exception, another exception occurred:

Traceback (most recent call last):
  File "/home/preetham_sathineni/anaconda2/envs/py37/lib/python3.7/site-packages/py4j/java_gateway.py", line 1115, in start
    self.socket.connect((self.address, self.port))
ConnectionRefusedError: [Errno 111] Connection refused
2021-07-26 00:41:02,516 - py4j.java_gateway - ERROR - An error occurred while trying to connect to the Java server (127.0.0.1:35157)
Traceback (most recent call last):
  File "/home/preetham_sathineni/anaconda2/envs/py37/lib/python3.7/site-packages/py4j/java_gateway.py", line 977, in _get_connection
    connection = self.deque.pop()
IndexError: pop from an empty deque

During handling of the above exception, another exception occurred:

Traceback (most recent call last):
  File "/home/preetham_sathineni/anaconda2/envs/py37/lib/python3.7/site-packages/py4j/java_gateway.py", line 1115, in start
    self.socket.connect((self.address, self.port))
ConnectionRefusedError: [Errno 111] Connection refused
2021-07-26 00:41:02,516 - py4j.java_gateway - ERROR - An error occurred while trying to connect to the Java server (127.0.0.1:35157)
Traceback (most recent call last):
  File "/home/preetham_sathineni/anaconda2/envs/py37/lib/python3.7/site-packages/py4j/java_gateway.py", line 977, in _get_connection
    connection = self.deque.pop()
IndexError: pop from an empty deque

During handling of the above exception, another exception occurred:

Traceback (most recent call last):
  File "/home/preetham_sathineni/anaconda2/envs/py37/lib/python3.7/site-packages/py4j/java_gateway.py", line 1115, in start
    self.socket.connect((self.address, self.port))
ConnectionRefusedError: [Errno 111] Connection refused
2021-07-26 00:41:02,516 - py4j.java_gateway - ERROR - An error occurred while trying to connect to the Java server (127.0.0.1:35157)
Traceback (most recent call last):
  File "/home/preetham_sathineni/anaconda2/envs/py37/lib/python3.7/site-packages/py4j/java_gateway.py", line 977, in _get_connection
    connection = self.deque.pop()
IndexError: pop from an empty deque

During handling of the above exception, another exception occurred:

Traceback (most recent call last):
  File "/home/preetham_sathineni/anaconda2/envs/py37/lib/python3.7/site-packages/py4j/java_gateway.py", line 1115, in start
    self.socket.connect((self.address, self.port))
ConnectionRefusedError: [Errno 111] Connection refused
2021-07-26 00:41:02,517 - py4j.java_gateway - ERROR - An error occurred while trying to connect to the Java server (127.0.0.1:35157)
Traceback (most recent call last):
  File "/home/preetham_sathineni/anaconda2/envs/py37/lib/python3.7/site-packages/py4j/java_gateway.py", line 977, in _get_connection
    connection = self.deque.pop()
IndexError: pop from an empty deque

During handling of the above exception, another exception occurred:

Traceback (most recent call last):
  File "/home/preetham_sathineni/anaconda2/envs/py37/lib/python3.7/site-packages/py4j/java_gateway.py", line 1115, in start
    self.socket.connect((self.address, self.port))
ConnectionRefusedError: [Errno 111] Connection refused
2021-07-26 00:41:02,517 - py4j.java_gateway - ERROR - An error occurred while trying to connect to the Java server (127.0.0.1:35157)
Traceback (most recent call last):
  File "/home/preetham_sathineni/anaconda2/envs/py37/lib/python3.7/site-packages/py4j/java_gateway.py", line 977, in _get_connection
    connection = self.deque.pop()
IndexError: pop from an empty deque

During handling of the above exception, another exception occurred:

Traceback (most recent call last):
  File "/home/preetham_sathineni/anaconda2/envs/py37/lib/python3.7/site-packages/py4j/java_gateway.py", line 1115, in start
    self.socket.connect((self.address, self.port))
ConnectionRefusedError: [Errno 111] Connection refused
2021-07-26 00:41:02,517 - py4j.java_gateway - ERROR - An error occurred while trying to connect to the Java server (127.0.0.1:35157)
Traceback (most recent call last):
  File "/home/preetham_sathineni/anaconda2/envs/py37/lib/python3.7/site-packages/py4j/java_gateway.py", line 977, in _get_connection
    connection = self.deque.pop()
IndexError: pop from an empty deque

During handling of the above exception, another exception occurred:

Traceback (most recent call last):
  File "/home/preetham_sathineni/anaconda2/envs/py37/lib/python3.7/site-packages/py4j/java_gateway.py", line 1115, in start
    self.socket.connect((self.address, self.port))
ConnectionRefusedError: [Errno 111] Connection refused
2021-07-26 00:41:02,517 - py4j.java_gateway - ERROR - An error occurred while trying to connect to the Java server (127.0.0.1:35157)
Traceback (most recent call last):
  File "/home/preetham_sathineni/anaconda2/envs/py37/lib/python3.7/site-packages/py4j/java_gateway.py", line 977, in _get_connection
    connection = self.deque.pop()
IndexError: pop from an empty deque

During handling of the above exception, another exception occurred:

Traceback (most recent call last):
  File "/home/preetham_sathineni/anaconda2/envs/py37/lib/python3.7/site-packages/py4j/java_gateway.py", line 1115, in start
    self.socket.connect((self.address, self.port))
ConnectionRefusedError: [Errno 111] Connection refused
