2021-07-18 08:36:25,947 - __main__ - INFO - Got the following arguments: ['our_newtest.py', '0.045', '1', '0.45', '8', '../CMineMR-Mapreduce-algorithm-to-extract-coverage-patterns-master/dataset/synthetic.txt', 'varying_mincs_mushroom_0.45_ultrmaxprodummy']
2021-07-18 08:36:31,692 - __main__ - INFO - started mining
2021-07-18 08:36:31,693 - __main__ - INFO - reading transactional data
2021-07-18 08:36:32,094 - __main__ - INFO - transactions size: 13738144
2021-07-18 08:36:32,094 - __main__ - INFO - First level mining
2021-07-18 08:36:35,378 - __main__ - INFO - Got first level patterns : 17  writing to file
2021-07-18 08:36:35,379 - __main__ - INFO - Generating second level candidateset
2021-07-18 08:36:35,521 - __main__ - INFO - saving 2 level patterns
2021-07-18 08:36:35,521 - __main__ - INFO - found 136 patterns
2021-07-18 08:36:35,521 - __main__ - INFO - computing patterns for level : 3
2021-07-18 08:36:35,920 - __main__ - INFO - saving 3 level patterns
2021-07-18 08:36:35,920 - __main__ - INFO - found 680 patterns
2021-07-18 08:36:35,920 - __main__ - INFO - computing patterns for level : 4
2021-07-18 08:36:36,424 - __main__ - INFO - saving 4 level patterns
2021-07-18 08:36:36,424 - __main__ - INFO - found 2380 patterns
2021-07-18 08:36:36,424 - __main__ - INFO - computing patterns for level : 5
2021-07-18 08:36:37,578 - __main__ - INFO - saving 5 level patterns
2021-07-18 08:36:37,579 - __main__ - INFO - found 6188 patterns
2021-07-18 08:36:37,579 - __main__ - INFO - computing patterns for level : 6
2021-07-18 08:36:40,718 - __main__ - INFO - saving 6 level patterns
2021-07-18 08:36:40,719 - __main__ - INFO - found 12364 patterns
2021-07-18 08:36:40,719 - __main__ - INFO - computing patterns for level : 7
2021-07-18 08:36:46,283 - __main__ - INFO - saving 7 level patterns
2021-07-18 08:36:46,285 - __main__ - INFO - found 19266 patterns
2021-07-18 08:36:46,285 - __main__ - INFO - computing patterns for level : 8
2021-07-18 08:36:54,953 - __main__ - INFO - saving 8 level patterns
2021-07-18 08:36:54,955 - __main__ - INFO - found 23506 patterns
2021-07-18 08:36:54,956 - __main__ - INFO - computing patterns for level : 9
2021-07-18 08:37:08,234 - __main__ - INFO - saving 9 level patterns
2021-07-18 08:37:08,237 - __main__ - INFO - found 20991 patterns
2021-07-18 08:37:08,237 - __main__ - INFO - computing patterns for level : 10
2021-07-18 08:37:23,002 - __main__ - INFO - saving 10 level patterns
2021-07-18 08:37:23,004 - __main__ - INFO - found 12061 patterns
2021-07-18 08:37:23,004 - __main__ - INFO - computing patterns for level : 11
2021-07-18 08:37:33,760 - __main__ - INFO - saving 11 level patterns
2021-07-18 08:37:33,762 - __main__ - INFO - found 3892 patterns
2021-07-18 08:37:33,762 - __main__ - INFO - computing patterns for level : 12
2021-07-18 08:37:37,356 - __main__ - INFO - saving 12 level patterns
2021-07-18 08:37:37,357 - __main__ - INFO - found 424 patterns
2021-07-18 08:37:37,357 - __main__ - INFO - computing patterns for level : 13
2021-07-18 08:37:37,894 - __main__ - INFO - saving 13 level patterns
2021-07-18 08:37:37,895 - __main__ - INFO - found 7 patterns
2021-07-18 08:37:37,895 - __main__ - INFO - computing patterns for level : 14
2021-07-18 08:37:38,004 - __main__ - INFO - saving 14 level patterns
2021-07-18 08:37:38,004 - __main__ - INFO - found 0 patterns
2021-07-18 08:37:38,004 - __main__ - INFO - computing patterns for level : 15
2021-07-18 08:37:38,122 - __main__ - INFO - saving 15 level patterns
2021-07-18 08:37:38,174 - __main__ - INFO - total time taken: 66.48178553581238
2021-07-18 08:37:38,175 - root - INFO - broadcast size:3754307
shuffle read:9076400
shuffle write:9071794
2021-07-18 08:42:20,409 - __main__ - INFO - Got the following arguments: ['our_newtest.py', '0.05', '1', '0.45', '8', '../CMineMR-Mapreduce-algorithm-to-extract-coverage-patterns-master/dataset/mushroom.txt', 'varying_mincs_mushroom_0.45_ultrmaxprodummy']
2021-07-18 08:42:26,269 - __main__ - INFO - started mining
2021-07-18 08:42:26,270 - __main__ - INFO - reading transactional data
2021-07-18 08:42:26,321 - __main__ - INFO - transactions size: 2151101
2021-07-18 08:42:26,322 - __main__ - INFO - First level mining
2021-07-18 08:42:28,251 - __main__ - INFO - Got first level patterns : 73  writing to file
2021-07-18 08:42:28,252 - __main__ - INFO - Generating second level candidateset
2021-07-18 08:42:28,511 - __main__ - INFO - saving 2 level patterns
2021-07-18 08:42:28,511 - __main__ - INFO - found 1448 patterns
2021-07-18 08:42:28,511 - __main__ - INFO - computing patterns for level : 3
2021-07-18 08:42:29,033 - __main__ - INFO - saving 3 level patterns
2021-07-18 08:42:29,034 - __main__ - INFO - found 12054 patterns
2021-07-18 08:42:29,034 - __main__ - INFO - computing patterns for level : 4
2021-07-18 08:42:30,430 - __main__ - INFO - saving 4 level patterns
2021-07-18 08:42:30,432 - __main__ - INFO - found 51314 patterns
2021-07-18 08:42:30,432 - __main__ - INFO - computing patterns for level : 5
2021-07-18 08:42:33,997 - __main__ - INFO - saving 5 level patterns
2021-07-18 08:42:34,004 - __main__ - INFO - found 127666 patterns
2021-07-18 08:42:34,004 - __main__ - INFO - computing patterns for level : 6
2021-07-18 08:42:40,545 - __main__ - INFO - saving 6 level patterns
2021-07-18 08:42:40,567 - __main__ - INFO - found 200771 patterns
2021-07-18 08:42:40,568 - __main__ - INFO - computing patterns for level : 7
2021-07-18 08:42:50,204 - __main__ - INFO - saving 7 level patterns
2021-07-18 08:42:50,236 - __main__ - INFO - found 207949 patterns
2021-07-18 08:42:50,236 - __main__ - INFO - computing patterns for level : 8
2021-07-18 08:43:01,123 - __main__ - INFO - saving 8 level patterns
2021-07-18 08:43:01,146 - __main__ - INFO - found 145382 patterns
2021-07-18 08:43:01,147 - __main__ - INFO - computing patterns for level : 9
2021-07-18 08:43:09,181 - __main__ - INFO - saving 9 level patterns
2021-07-18 08:43:09,195 - __main__ - INFO - found 69034 patterns
2021-07-18 08:43:09,195 - __main__ - INFO - computing patterns for level : 10
2021-07-18 08:43:13,225 - __main__ - INFO - saving 10 level patterns
2021-07-18 08:43:13,231 - __main__ - INFO - found 21797 patterns
2021-07-18 08:43:13,231 - __main__ - INFO - computing patterns for level : 11
2021-07-18 08:43:14,829 - __main__ - INFO - saving 11 level patterns
2021-07-18 08:43:14,830 - __main__ - INFO - found 4205 patterns
2021-07-18 08:43:14,830 - __main__ - INFO - computing patterns for level : 12
2021-07-18 08:43:15,212 - __main__ - INFO - saving 12 level patterns
2021-07-18 08:43:15,212 - __main__ - INFO - found 372 patterns
2021-07-18 08:43:15,212 - __main__ - INFO - computing patterns for level : 13
2021-07-18 08:43:15,335 - __main__ - INFO - saving 13 level patterns
2021-07-18 08:43:15,335 - __main__ - INFO - found 0 patterns
2021-07-18 08:43:15,335 - __main__ - INFO - computing patterns for level : 14
2021-07-18 08:43:15,432 - __main__ - INFO - saving 14 level patterns
2021-07-18 08:43:15,442 - __main__ - INFO - total time taken: 49.17236256599426
2021-07-18 08:43:15,443 - root - INFO - broadcast size:558345
shuffle read:71017306
shuffle write:70966538
2021-07-23 20:34:15,015 - __main__ - INFO - Got the following arguments: ['our_newtest.py', '0.03', '1', '0.45', '8', '../CMineMR-Mapreduce-algorithm-to-extract-coverage-patterns-master/dataset/synthetic.txt', 'varying_mincs_mushroom_0.45_ultrmaxprodummy']
2021-07-23 20:34:23,180 - __main__ - INFO - started mining
2021-07-23 20:34:23,181 - __main__ - INFO - reading transactional data
2021-07-23 20:34:23,423 - __main__ - INFO - First level mining
2021-07-23 20:34:27,071 - __main__ - INFO - Got first level patterns : 60  writing to file
2021-07-23 20:34:27,080 - __main__ - INFO - Generating second level candidateset
2021-07-23 20:34:27,571 - __main__ - INFO - saving 2 level patterns
2021-07-23 20:34:27,571 - __main__ - INFO - found 1770 patterns
2021-07-23 20:34:27,572 - __main__ - INFO - computing patterns for level : 3
2021-07-23 20:34:31,325 - __main__ - INFO - saving 3 level patterns
2021-07-23 20:34:31,326 - __main__ - INFO - found 34214 patterns
2021-07-23 20:34:31,326 - __main__ - INFO - computing patterns for level : 4
2021-07-23 20:35:07,890 - __main__ - INFO - saving 4 level patterns
2021-07-23 20:35:07,900 - __main__ - INFO - found 486937 patterns
2021-07-23 20:35:07,900 - __main__ - INFO - computing patterns for level : 5
2021-07-23 20:42:40,516 - __main__ - INFO - saving 5 level patterns
2021-07-23 20:42:40,631 - __main__ - INFO - found 5430612 patterns
2021-07-23 20:42:40,631 - __main__ - INFO - computing patterns for level : 6
2021-07-23 20:42:53,263 - py4j.java_gateway - INFO - Error while receiving.
Traceback (most recent call last):
  File "/home/preetham_sathineni/anaconda2/envs/py37/lib/python3.7/site-packages/py4j/java_gateway.py", line 1207, in send_command
    raise Py4JNetworkError("Answer from Java side is empty")
py4j.protocol.Py4JNetworkError: Answer from Java side is empty
2021-07-23 20:42:53,265 - root - ERROR - Exception while sending command.
Traceback (most recent call last):
  File "/home/preetham_sathineni/anaconda2/envs/py37/lib/python3.7/site-packages/py4j/java_gateway.py", line 1207, in send_command
    raise Py4JNetworkError("Answer from Java side is empty")
py4j.protocol.Py4JNetworkError: Answer from Java side is empty

During handling of the above exception, another exception occurred:

Traceback (most recent call last):
  File "/home/preetham_sathineni/anaconda2/envs/py37/lib/python3.7/site-packages/py4j/java_gateway.py", line 1033, in send_command
    response = connection.send_command(command)
  File "/home/preetham_sathineni/anaconda2/envs/py37/lib/python3.7/site-packages/py4j/java_gateway.py", line 1212, in send_command
    "Error while receiving", e, proto.ERROR_ON_RECEIVE)
py4j.protocol.Py4JNetworkError: Error while receiving
2021-07-23 20:42:53,265 - py4j.java_gateway - ERROR - An error occurred while trying to connect to the Java server (127.0.0.1:41415)
Traceback (most recent call last):
  File "/home/preetham_sathineni/anaconda2/envs/py37/lib/python3.7/site-packages/py4j/java_gateway.py", line 977, in _get_connection
    connection = self.deque.pop()
IndexError: pop from an empty deque

During handling of the above exception, another exception occurred:

Traceback (most recent call last):
  File "/home/preetham_sathineni/anaconda2/envs/py37/lib/python3.7/site-packages/py4j/java_gateway.py", line 1115, in start
    self.socket.connect((self.address, self.port))
ConnectionRefusedError: [Errno 111] Connection refused
2021-07-23 20:42:53,266 - py4j.java_gateway - ERROR - An error occurred while trying to connect to the Java server (127.0.0.1:41415)
Traceback (most recent call last):
  File "/home/preetham_sathineni/anaconda2/envs/py37/lib/python3.7/site-packages/py4j/java_gateway.py", line 977, in _get_connection
    connection = self.deque.pop()
IndexError: pop from an empty deque

During handling of the above exception, another exception occurred:

Traceback (most recent call last):
  File "/home/preetham_sathineni/anaconda2/envs/py37/lib/python3.7/site-packages/py4j/java_gateway.py", line 1115, in start
    self.socket.connect((self.address, self.port))
ConnectionRefusedError: [Errno 111] Connection refused
2021-07-23 20:42:53,266 - py4j.java_gateway - ERROR - An error occurred while trying to connect to the Java server (127.0.0.1:41415)
Traceback (most recent call last):
  File "/home/preetham_sathineni/anaconda2/envs/py37/lib/python3.7/site-packages/py4j/java_gateway.py", line 977, in _get_connection
    connection = self.deque.pop()
IndexError: pop from an empty deque

During handling of the above exception, another exception occurred:

Traceback (most recent call last):
  File "/home/preetham_sathineni/anaconda2/envs/py37/lib/python3.7/site-packages/py4j/java_gateway.py", line 1115, in start
    self.socket.connect((self.address, self.port))
ConnectionRefusedError: [Errno 111] Connection refused
2021-07-23 20:42:53,266 - py4j.java_gateway - ERROR - An error occurred while trying to connect to the Java server (127.0.0.1:41415)
Traceback (most recent call last):
  File "/home/preetham_sathineni/anaconda2/envs/py37/lib/python3.7/site-packages/py4j/java_gateway.py", line 977, in _get_connection
    connection = self.deque.pop()
IndexError: pop from an empty deque

During handling of the above exception, another exception occurred:

Traceback (most recent call last):
  File "/home/preetham_sathineni/anaconda2/envs/py37/lib/python3.7/site-packages/py4j/java_gateway.py", line 1115, in start
    self.socket.connect((self.address, self.port))
ConnectionRefusedError: [Errno 111] Connection refused
2021-07-23 20:42:53,266 - py4j.java_gateway - ERROR - An error occurred while trying to connect to the Java server (127.0.0.1:41415)
Traceback (most recent call last):
  File "/home/preetham_sathineni/anaconda2/envs/py37/lib/python3.7/site-packages/py4j/java_gateway.py", line 977, in _get_connection
    connection = self.deque.pop()
IndexError: pop from an empty deque

During handling of the above exception, another exception occurred:

Traceback (most recent call last):
  File "/home/preetham_sathineni/anaconda2/envs/py37/lib/python3.7/site-packages/py4j/java_gateway.py", line 1115, in start
    self.socket.connect((self.address, self.port))
ConnectionRefusedError: [Errno 111] Connection refused
2021-07-23 20:42:53,267 - py4j.java_gateway - ERROR - An error occurred while trying to connect to the Java server (127.0.0.1:41415)
Traceback (most recent call last):
  File "/home/preetham_sathineni/anaconda2/envs/py37/lib/python3.7/site-packages/py4j/java_gateway.py", line 977, in _get_connection
    connection = self.deque.pop()
IndexError: pop from an empty deque

During handling of the above exception, another exception occurred:

Traceback (most recent call last):
  File "/home/preetham_sathineni/anaconda2/envs/py37/lib/python3.7/site-packages/py4j/java_gateway.py", line 1115, in start
    self.socket.connect((self.address, self.port))
ConnectionRefusedError: [Errno 111] Connection refused
2021-07-23 20:42:54,232 - py4j.java_gateway - ERROR - An error occurred while trying to connect to the Java server (127.0.0.1:41415)
Traceback (most recent call last):
  File "/home/preetham_sathineni/anaconda2/envs/py37/lib/python3.7/site-packages/py4j/java_gateway.py", line 977, in _get_connection
    connection = self.deque.pop()
IndexError: pop from an empty deque

During handling of the above exception, another exception occurred:

Traceback (most recent call last):
  File "/home/preetham_sathineni/anaconda2/envs/py37/lib/python3.7/site-packages/py4j/java_gateway.py", line 1115, in start
    self.socket.connect((self.address, self.port))
ConnectionRefusedError: [Errno 111] Connection refused
2021-07-23 20:42:54,232 - py4j.java_gateway - ERROR - An error occurred while trying to connect to the Java server (127.0.0.1:41415)
Traceback (most recent call last):
  File "/home/preetham_sathineni/anaconda2/envs/py37/lib/python3.7/site-packages/py4j/java_gateway.py", line 977, in _get_connection
    connection = self.deque.pop()
IndexError: pop from an empty deque

During handling of the above exception, another exception occurred:

Traceback (most recent call last):
  File "/home/preetham_sathineni/anaconda2/envs/py37/lib/python3.7/site-packages/py4j/java_gateway.py", line 1115, in start
    self.socket.connect((self.address, self.port))
ConnectionRefusedError: [Errno 111] Connection refused
2021-07-23 20:42:54,233 - py4j.java_gateway - ERROR - An error occurred while trying to connect to the Java server (127.0.0.1:41415)
Traceback (most recent call last):
  File "/home/preetham_sathineni/anaconda2/envs/py37/lib/python3.7/site-packages/py4j/java_gateway.py", line 977, in _get_connection
    connection = self.deque.pop()
IndexError: pop from an empty deque

During handling of the above exception, another exception occurred:

Traceback (most recent call last):
  File "/home/preetham_sathineni/anaconda2/envs/py37/lib/python3.7/site-packages/py4j/java_gateway.py", line 1115, in start
    self.socket.connect((self.address, self.port))
ConnectionRefusedError: [Errno 111] Connection refused
2021-07-23 20:42:54,233 - py4j.java_gateway - ERROR - An error occurred while trying to connect to the Java server (127.0.0.1:41415)
Traceback (most recent call last):
  File "/home/preetham_sathineni/anaconda2/envs/py37/lib/python3.7/site-packages/py4j/java_gateway.py", line 977, in _get_connection
    connection = self.deque.pop()
IndexError: pop from an empty deque

During handling of the above exception, another exception occurred:

Traceback (most recent call last):
  File "/home/preetham_sathineni/anaconda2/envs/py37/lib/python3.7/site-packages/py4j/java_gateway.py", line 1115, in start
    self.socket.connect((self.address, self.port))
ConnectionRefusedError: [Errno 111] Connection refused
2021-07-23 20:42:54,233 - py4j.java_gateway - ERROR - An error occurred while trying to connect to the Java server (127.0.0.1:41415)
Traceback (most recent call last):
  File "/home/preetham_sathineni/anaconda2/envs/py37/lib/python3.7/site-packages/py4j/java_gateway.py", line 977, in _get_connection
    connection = self.deque.pop()
IndexError: pop from an empty deque

During handling of the above exception, another exception occurred:

Traceback (most recent call last):
  File "/home/preetham_sathineni/anaconda2/envs/py37/lib/python3.7/site-packages/py4j/java_gateway.py", line 1115, in start
    self.socket.connect((self.address, self.port))
ConnectionRefusedError: [Errno 111] Connection refused
2021-07-23 20:42:54,234 - py4j.java_gateway - ERROR - An error occurred while trying to connect to the Java server (127.0.0.1:41415)
Traceback (most recent call last):
  File "/home/preetham_sathineni/anaconda2/envs/py37/lib/python3.7/site-packages/py4j/java_gateway.py", line 977, in _get_connection
    connection = self.deque.pop()
IndexError: pop from an empty deque

During handling of the above exception, another exception occurred:

Traceback (most recent call last):
  File "/home/preetham_sathineni/anaconda2/envs/py37/lib/python3.7/site-packages/py4j/java_gateway.py", line 1115, in start
    self.socket.connect((self.address, self.port))
ConnectionRefusedError: [Errno 111] Connection refused
2021-07-23 20:42:54,234 - py4j.java_gateway - ERROR - An error occurred while trying to connect to the Java server (127.0.0.1:41415)
Traceback (most recent call last):
  File "/home/preetham_sathineni/anaconda2/envs/py37/lib/python3.7/site-packages/py4j/java_gateway.py", line 977, in _get_connection
    connection = self.deque.pop()
IndexError: pop from an empty deque

During handling of the above exception, another exception occurred:

Traceback (most recent call last):
  File "/home/preetham_sathineni/anaconda2/envs/py37/lib/python3.7/site-packages/py4j/java_gateway.py", line 1115, in start
    self.socket.connect((self.address, self.port))
ConnectionRefusedError: [Errno 111] Connection refused
2021-07-23 20:42:54,234 - py4j.java_gateway - ERROR - An error occurred while trying to connect to the Java server (127.0.0.1:41415)
Traceback (most recent call last):
  File "/home/preetham_sathineni/anaconda2/envs/py37/lib/python3.7/site-packages/py4j/java_gateway.py", line 977, in _get_connection
    connection = self.deque.pop()
IndexError: pop from an empty deque

During handling of the above exception, another exception occurred:

Traceback (most recent call last):
  File "/home/preetham_sathineni/anaconda2/envs/py37/lib/python3.7/site-packages/py4j/java_gateway.py", line 1115, in start
    self.socket.connect((self.address, self.port))
ConnectionRefusedError: [Errno 111] Connection refused
2021-07-23 20:42:54,234 - py4j.java_gateway - ERROR - An error occurred while trying to connect to the Java server (127.0.0.1:41415)
Traceback (most recent call last):
  File "/home/preetham_sathineni/anaconda2/envs/py37/lib/python3.7/site-packages/py4j/java_gateway.py", line 977, in _get_connection
    connection = self.deque.pop()
IndexError: pop from an empty deque

During handling of the above exception, another exception occurred:

Traceback (most recent call last):
  File "/home/preetham_sathineni/anaconda2/envs/py37/lib/python3.7/site-packages/py4j/java_gateway.py", line 1115, in start
    self.socket.connect((self.address, self.port))
ConnectionRefusedError: [Errno 111] Connection refused
2021-07-23 20:42:54,235 - py4j.java_gateway - ERROR - An error occurred while trying to connect to the Java server (127.0.0.1:41415)
Traceback (most recent call last):
  File "/home/preetham_sathineni/anaconda2/envs/py37/lib/python3.7/site-packages/py4j/java_gateway.py", line 977, in _get_connection
    connection = self.deque.pop()
IndexError: pop from an empty deque

During handling of the above exception, another exception occurred:

Traceback (most recent call last):
  File "/home/preetham_sathineni/anaconda2/envs/py37/lib/python3.7/site-packages/py4j/java_gateway.py", line 1115, in start
    self.socket.connect((self.address, self.port))
ConnectionRefusedError: [Errno 111] Connection refused
2021-07-23 20:42:54,235 - py4j.java_gateway - ERROR - An error occurred while trying to connect to the Java server (127.0.0.1:41415)
Traceback (most recent call last):
  File "/home/preetham_sathineni/anaconda2/envs/py37/lib/python3.7/site-packages/py4j/java_gateway.py", line 977, in _get_connection
    connection = self.deque.pop()
IndexError: pop from an empty deque

During handling of the above exception, another exception occurred:

Traceback (most recent call last):
  File "/home/preetham_sathineni/anaconda2/envs/py37/lib/python3.7/site-packages/py4j/java_gateway.py", line 1115, in start
    self.socket.connect((self.address, self.port))
ConnectionRefusedError: [Errno 111] Connection refused
2021-07-23 20:42:54,235 - py4j.java_gateway - ERROR - An error occurred while trying to connect to the Java server (127.0.0.1:41415)
Traceback (most recent call last):
  File "/home/preetham_sathineni/anaconda2/envs/py37/lib/python3.7/site-packages/py4j/java_gateway.py", line 977, in _get_connection
    connection = self.deque.pop()
IndexError: pop from an empty deque

During handling of the above exception, another exception occurred:

Traceback (most recent call last):
  File "/home/preetham_sathineni/anaconda2/envs/py37/lib/python3.7/site-packages/py4j/java_gateway.py", line 1115, in start
    self.socket.connect((self.address, self.port))
ConnectionRefusedError: [Errno 111] Connection refused
2021-07-23 20:42:54,235 - py4j.java_gateway - ERROR - An error occurred while trying to connect to the Java server (127.0.0.1:41415)
Traceback (most recent call last):
  File "/home/preetham_sathineni/anaconda2/envs/py37/lib/python3.7/site-packages/py4j/java_gateway.py", line 977, in _get_connection
    connection = self.deque.pop()
IndexError: pop from an empty deque

During handling of the above exception, another exception occurred:

Traceback (most recent call last):
  File "/home/preetham_sathineni/anaconda2/envs/py37/lib/python3.7/site-packages/py4j/java_gateway.py", line 1115, in start
    self.socket.connect((self.address, self.port))
ConnectionRefusedError: [Errno 111] Connection refused
2021-07-23 20:42:54,236 - py4j.java_gateway - ERROR - An error occurred while trying to connect to the Java server (127.0.0.1:41415)
Traceback (most recent call last):
  File "/home/preetham_sathineni/anaconda2/envs/py37/lib/python3.7/site-packages/py4j/java_gateway.py", line 977, in _get_connection
    connection = self.deque.pop()
IndexError: pop from an empty deque

During handling of the above exception, another exception occurred:

Traceback (most recent call last):
  File "/home/preetham_sathineni/anaconda2/envs/py37/lib/python3.7/site-packages/py4j/java_gateway.py", line 1115, in start
    self.socket.connect((self.address, self.port))
ConnectionRefusedError: [Errno 111] Connection refused
2021-07-23 20:42:54,236 - py4j.java_gateway - ERROR - An error occurred while trying to connect to the Java server (127.0.0.1:41415)
Traceback (most recent call last):
  File "/home/preetham_sathineni/anaconda2/envs/py37/lib/python3.7/site-packages/py4j/java_gateway.py", line 977, in _get_connection
    connection = self.deque.pop()
IndexError: pop from an empty deque

During handling of the above exception, another exception occurred:

Traceback (most recent call last):
  File "/home/preetham_sathineni/anaconda2/envs/py37/lib/python3.7/site-packages/py4j/java_gateway.py", line 1115, in start
    self.socket.connect((self.address, self.port))
ConnectionRefusedError: [Errno 111] Connection refused
2021-07-23 20:42:54,236 - py4j.java_gateway - ERROR - An error occurred while trying to connect to the Java server (127.0.0.1:41415)
Traceback (most recent call last):
  File "/home/preetham_sathineni/anaconda2/envs/py37/lib/python3.7/site-packages/py4j/java_gateway.py", line 977, in _get_connection
    connection = self.deque.pop()
IndexError: pop from an empty deque

During handling of the above exception, another exception occurred:

Traceback (most recent call last):
  File "/home/preetham_sathineni/anaconda2/envs/py37/lib/python3.7/site-packages/py4j/java_gateway.py", line 1115, in start
    self.socket.connect((self.address, self.port))
ConnectionRefusedError: [Errno 111] Connection refused
2021-07-23 20:42:54,236 - py4j.java_gateway - ERROR - An error occurred while trying to connect to the Java server (127.0.0.1:41415)
Traceback (most recent call last):
  File "/home/preetham_sathineni/anaconda2/envs/py37/lib/python3.7/site-packages/py4j/java_gateway.py", line 977, in _get_connection
    connection = self.deque.pop()
IndexError: pop from an empty deque

During handling of the above exception, another exception occurred:

Traceback (most recent call last):
  File "/home/preetham_sathineni/anaconda2/envs/py37/lib/python3.7/site-packages/py4j/java_gateway.py", line 1115, in start
    self.socket.connect((self.address, self.port))
ConnectionRefusedError: [Errno 111] Connection refused
2021-07-25 00:36:17,541 - __main__ - INFO - Got the following arguments: ['our_newtest.py', '0.04', '1', '0.45', '16', '../CMineMR-Mapreduce-algorithm-to-extract-coverage-patterns-master/dataset/mushroom.txt', 'varying_mincs_mushroom_0.45_ultrmaxprodummy']
2021-07-25 00:36:23,742 - __main__ - INFO - started mining
2021-07-25 00:36:23,742 - __main__ - INFO - reading transactional data
2021-07-25 00:36:23,768 - __main__ - INFO - First level mining
2021-07-25 00:36:25,926 - __main__ - INFO - Got first level patterns : 79  writing to file
2021-07-25 00:36:25,928 - __main__ - INFO - Generating second level candidateset
2021-07-25 00:36:26,221 - __main__ - INFO - saving 2 level patterns
2021-07-25 00:36:26,221 - __main__ - INFO - found 1784 patterns
2021-07-25 00:36:26,221 - __main__ - INFO - computing patterns for level : 3
2021-07-25 00:36:26,770 - __main__ - INFO - saving 3 level patterns
2021-07-25 00:36:26,770 - __main__ - INFO - found 18316 patterns
2021-07-25 00:36:26,770 - __main__ - INFO - computing patterns for level : 4
2021-07-25 00:36:28,034 - __main__ - INFO - saving 4 level patterns
2021-07-25 00:36:28,037 - __main__ - INFO - found 103200 patterns
2021-07-25 00:36:28,037 - __main__ - INFO - computing patterns for level : 5
2021-07-25 00:36:31,897 - __main__ - INFO - saving 5 level patterns
2021-07-25 00:36:31,915 - __main__ - INFO - found 358375 patterns
2021-07-25 00:36:31,915 - __main__ - INFO - computing patterns for level : 6
2021-07-25 00:36:44,562 - __main__ - INFO - saving 6 level patterns
2021-07-25 00:36:44,648 - __main__ - INFO - found 819604 patterns
2021-07-25 00:36:44,648 - __main__ - INFO - computing patterns for level : 7
2021-07-25 00:37:08,398 - __main__ - INFO - saving 7 level patterns
2021-07-25 00:37:08,557 - __main__ - INFO - found 1285462 patterns
2021-07-25 00:37:08,557 - __main__ - INFO - computing patterns for level : 8
2021-07-25 00:37:45,490 - __main__ - INFO - saving 8 level patterns
2021-07-25 00:37:45,704 - __main__ - INFO - found 1434746 patterns
2021-07-25 00:37:45,704 - __main__ - INFO - computing patterns for level : 9
2021-07-25 00:38:26,987 - __main__ - INFO - saving 9 level patterns
2021-07-25 00:38:27,237 - __main__ - INFO - found 1169852 patterns
2021-07-25 00:38:27,238 - __main__ - INFO - computing patterns for level : 10
2021-07-25 00:39:02,481 - __main__ - INFO - saving 10 level patterns
2021-07-25 00:39:02,650 - __main__ - INFO - found 705929 patterns
2021-07-25 00:39:02,650 - __main__ - INFO - computing patterns for level : 11
2021-07-25 00:39:26,470 - __main__ - INFO - saving 11 level patterns
2021-07-25 00:39:26,582 - __main__ - INFO - found 315091 patterns
2021-07-25 00:39:26,582 - __main__ - INFO - computing patterns for level : 12
2021-07-25 00:39:37,768 - __main__ - INFO - saving 12 level patterns
2021-07-25 00:39:37,798 - __main__ - INFO - found 102174 patterns
2021-07-25 00:39:37,799 - __main__ - INFO - computing patterns for level : 13
2021-07-25 00:39:41,885 - __main__ - INFO - saving 13 level patterns
2021-07-25 00:39:41,895 - __main__ - INFO - found 22927 patterns
2021-07-25 00:39:41,895 - __main__ - INFO - computing patterns for level : 14
2021-07-25 00:39:43,387 - __main__ - INFO - saving 14 level patterns
2021-07-25 00:39:43,390 - __main__ - INFO - found 3176 patterns
2021-07-25 00:39:43,390 - __main__ - INFO - computing patterns for level : 15
2021-07-25 00:39:43,686 - __main__ - INFO - saving 15 level patterns
2021-07-25 00:39:43,687 - __main__ - INFO - found 201 patterns
2021-07-25 00:39:43,687 - __main__ - INFO - computing patterns for level : 16
2021-07-25 00:39:43,810 - __main__ - INFO - saving 16 level patterns
2021-07-25 00:39:43,810 - __main__ - INFO - found 0 patterns
2021-07-25 00:39:43,810 - __main__ - INFO - computing patterns for level : 17
2021-07-25 00:39:43,920 - __main__ - INFO - saving 17 level patterns
2021-07-25 00:39:43,932 - __main__ - INFO - total time taken: 200.1899597644806
2021-07-25 00:39:43,933 - root - INFO - broadcast size:0
shuffle read:0
shuffle write:0
