2021-07-17 14:08:22,798 - __main__ - INFO - Got the following arguments: ['our_newtest.py', '0.045', '1', '0.35', '8', '../CMineMR-Mapreduce-algorithm-to-extract-coverage-patterns-master/dataset/synthetic.txt', 'varying_mincs_mushroom_0.35_ultrmaxprodummy']
2021-07-17 14:08:28,282 - __main__ - INFO - started mining
2021-07-17 14:08:28,282 - __main__ - INFO - reading transactional data
2021-07-17 14:08:28,673 - __main__ - INFO - transactions size: 13738144
2021-07-17 14:08:28,673 - __main__ - INFO - First level mining
2021-07-17 14:08:31,566 - __main__ - INFO - Got first level patterns : 17  writing to file
2021-07-17 14:08:31,567 - __main__ - INFO - Generating second level candidateset
2021-07-17 14:08:31,701 - __main__ - INFO - saving 2 level patterns
2021-07-17 14:08:31,701 - __main__ - INFO - found 136 patterns
2021-07-17 14:08:31,701 - __main__ - INFO - computing patterns for level : 3
2021-07-17 14:08:32,069 - __main__ - INFO - saving 3 level patterns
2021-07-17 14:08:32,070 - __main__ - INFO - found 680 patterns
2021-07-17 14:08:32,070 - __main__ - INFO - computing patterns for level : 4
2021-07-17 14:08:32,522 - __main__ - INFO - saving 4 level patterns
2021-07-17 14:08:32,523 - __main__ - INFO - found 2379 patterns
2021-07-17 14:08:32,523 - __main__ - INFO - computing patterns for level : 5
2021-07-17 14:08:33,728 - __main__ - INFO - saving 5 level patterns
2021-07-17 14:08:33,729 - __main__ - INFO - found 6140 patterns
2021-07-17 14:08:33,729 - __main__ - INFO - computing patterns for level : 6
2021-07-17 14:08:36,940 - __main__ - INFO - saving 6 level patterns
2021-07-17 14:08:36,941 - __main__ - INFO - found 11482 patterns
2021-07-17 14:08:36,942 - __main__ - INFO - computing patterns for level : 7
2021-07-17 14:08:42,147 - __main__ - INFO - saving 7 level patterns
2021-07-17 14:08:42,148 - __main__ - INFO - found 14587 patterns
2021-07-17 14:08:42,148 - __main__ - INFO - computing patterns for level : 8
2021-07-17 14:08:48,500 - __main__ - INFO - saving 8 level patterns
2021-07-17 14:08:48,503 - __main__ - INFO - found 10416 patterns
2021-07-17 14:08:48,503 - __main__ - INFO - computing patterns for level : 9
2021-07-17 14:08:54,459 - __main__ - INFO - saving 9 level patterns
2021-07-17 14:08:54,460 - __main__ - INFO - found 3073 patterns
2021-07-17 14:08:54,460 - __main__ - INFO - computing patterns for level : 10
2021-07-17 14:08:56,814 - __main__ - INFO - saving 10 level patterns
2021-07-17 14:08:56,814 - __main__ - INFO - found 115 patterns
2021-07-17 14:08:56,814 - __main__ - INFO - computing patterns for level : 11
2021-07-17 14:08:57,008 - __main__ - INFO - saving 11 level patterns
2021-07-17 14:08:57,008 - __main__ - INFO - found 0 patterns
2021-07-17 14:08:57,008 - __main__ - INFO - computing patterns for level : 12
2021-07-17 14:08:57,103 - __main__ - INFO - saving 12 level patterns
2021-07-17 14:08:57,143 - __main__ - INFO - total time taken: 28.861250400543213
2021-07-17 14:08:57,144 - root - INFO - broadcast size:3754307
shuffle read:4190441
shuffle write:4185835
2021-07-17 14:11:51,368 - __main__ - INFO - Got the following arguments: ['our_newtest.py', '0.045', '1', '0.35', '8', '../CMineMR-Mapreduce-algorithm-to-extract-coverage-patterns-master/dataset/synthetic.txt', 'varying_mincs_mushroom_0.35_ultrmaxprodummy']
2021-07-17 14:11:56,702 - __main__ - INFO - started mining
2021-07-17 14:11:56,703 - __main__ - INFO - reading transactional data
2021-07-17 14:11:57,100 - __main__ - INFO - transactions size: 13738144
2021-07-17 14:11:57,100 - __main__ - INFO - First level mining
2021-07-17 14:12:00,055 - __main__ - INFO - Got first level patterns : 17  writing to file
2021-07-17 14:12:00,057 - __main__ - INFO - Generating second level candidateset
2021-07-17 14:12:00,190 - __main__ - INFO - saving 2 level patterns
2021-07-17 14:12:00,190 - __main__ - INFO - found 136 patterns
2021-07-17 14:12:00,190 - __main__ - INFO - computing patterns for level : 3
2021-07-17 14:12:25,463 - __main__ - INFO - Got the following arguments: ['our_newtest.py', '0.045', '1', '0.35', '8', '../CMineMR-Mapreduce-algorithm-to-extract-coverage-patterns-master/dataset/synthetic.txt', 'varying_mincs_mushroom_0.35_ultrmaxprodummy']
2021-07-17 14:12:30,840 - __main__ - INFO - started mining
2021-07-17 14:12:30,840 - __main__ - INFO - reading transactional data
2021-07-17 14:12:31,248 - __main__ - INFO - transactions size: 13738144
2021-07-17 14:12:31,248 - __main__ - INFO - First level mining
2021-07-17 14:12:34,172 - __main__ - INFO - Got first level patterns : 17  writing to file
2021-07-17 14:12:34,173 - __main__ - INFO - Generating second level candidateset
2021-07-17 14:12:34,318 - __main__ - INFO - saving 2 level patterns
2021-07-17 14:12:34,319 - __main__ - INFO - found 136 patterns
2021-07-17 14:12:34,319 - __main__ - INFO - computing patterns for level : 3
2021-07-17 14:12:34,721 - __main__ - INFO - saving 3 level patterns
2021-07-17 14:12:34,721 - __main__ - INFO - found 680 patterns
2021-07-17 14:12:34,721 - __main__ - INFO - computing patterns for level : 4
2021-07-17 14:12:35,145 - __main__ - INFO - saving 4 level patterns
2021-07-17 14:12:35,145 - __main__ - INFO - found 2379 patterns
2021-07-17 14:12:35,145 - __main__ - INFO - computing patterns for level : 5
2021-07-17 14:12:36,328 - __main__ - INFO - saving 5 level patterns
2021-07-17 14:12:36,328 - __main__ - INFO - found 6140 patterns
2021-07-17 14:12:36,328 - __main__ - INFO - computing patterns for level : 6
2021-07-17 14:12:39,360 - __main__ - INFO - saving 6 level patterns
2021-07-17 14:12:39,361 - __main__ - INFO - found 11482 patterns
2021-07-17 14:12:39,361 - __main__ - INFO - computing patterns for level : 7
2021-07-17 14:12:44,214 - __main__ - INFO - saving 7 level patterns
2021-07-17 14:12:44,215 - __main__ - INFO - found 14587 patterns
2021-07-17 14:12:44,215 - __main__ - INFO - computing patterns for level : 8
2021-07-17 14:12:50,543 - __main__ - INFO - saving 8 level patterns
2021-07-17 14:12:50,545 - __main__ - INFO - found 10416 patterns
2021-07-17 14:12:50,545 - __main__ - INFO - computing patterns for level : 9
2021-07-17 14:12:56,293 - __main__ - INFO - saving 9 level patterns
2021-07-17 14:12:56,294 - __main__ - INFO - found 3073 patterns
2021-07-17 14:12:56,294 - __main__ - INFO - computing patterns for level : 10
2021-07-17 14:12:58,632 - __main__ - INFO - saving 10 level patterns
2021-07-17 14:12:58,633 - __main__ - INFO - found 115 patterns
2021-07-17 14:12:58,633 - __main__ - INFO - computing patterns for level : 11
2021-07-17 14:12:58,854 - __main__ - INFO - saving 11 level patterns
2021-07-17 14:12:58,855 - __main__ - INFO - found 0 patterns
2021-07-17 14:12:58,855 - __main__ - INFO - computing patterns for level : 12
2021-07-17 14:12:58,943 - __main__ - INFO - saving 12 level patterns
2021-07-17 14:12:58,989 - __main__ - INFO - total time taken: 28.149495601654053
2021-07-17 14:12:58,990 - root - INFO - broadcast size:3754307
shuffle read:4190441
shuffle write:4185835
2021-07-18 08:27:21,102 - __main__ - INFO - Got the following arguments: ['our_newtest.py', '0.045', '1', '0.35', '8', '../CMineMR-Mapreduce-algorithm-to-extract-coverage-patterns-master/dataset/synthetic.txt', 'varying_mincs_mushroom_0.35_ultrmaxprodummy']
2021-07-18 08:27:25,618 - __main__ - INFO - started mining
2021-07-18 08:27:25,619 - __main__ - INFO - reading transactional data
2021-07-18 08:27:26,092 - __main__ - INFO - transactions size: 13738144
2021-07-18 08:27:26,093 - __main__ - INFO - First level mining
2021-07-18 08:27:29,375 - __main__ - INFO - Got first level patterns : 17  writing to file
2021-07-18 08:27:29,386 - __main__ - INFO - Generating second level candidateset
2021-07-18 08:27:29,522 - __main__ - INFO - saving 2 level patterns
2021-07-18 08:27:29,523 - __main__ - INFO - found 136 patterns
2021-07-18 08:27:29,523 - __main__ - INFO - computing patterns for level : 3
2021-07-18 08:27:29,932 - __main__ - INFO - saving 3 level patterns
2021-07-18 08:27:29,932 - __main__ - INFO - found 680 patterns
2021-07-18 08:27:29,932 - __main__ - INFO - computing patterns for level : 4
2021-07-18 08:27:30,384 - __main__ - INFO - saving 4 level patterns
2021-07-18 08:27:30,384 - __main__ - INFO - found 2379 patterns
2021-07-18 08:27:30,384 - __main__ - INFO - computing patterns for level : 5
2021-07-18 08:27:31,731 - __main__ - INFO - saving 5 level patterns
2021-07-18 08:27:31,731 - __main__ - INFO - found 6140 patterns
2021-07-18 08:27:31,731 - __main__ - INFO - computing patterns for level : 6
2021-07-18 08:27:34,803 - __main__ - INFO - saving 6 level patterns
2021-07-18 08:27:34,804 - __main__ - INFO - found 11482 patterns
2021-07-18 08:27:34,804 - __main__ - INFO - computing patterns for level : 7
2021-07-18 08:27:39,788 - __main__ - INFO - saving 7 level patterns
2021-07-18 08:27:39,790 - __main__ - INFO - found 14587 patterns
2021-07-18 08:27:39,790 - __main__ - INFO - computing patterns for level : 8
2021-07-18 08:27:46,665 - __main__ - INFO - saving 8 level patterns
2021-07-18 08:27:46,666 - __main__ - INFO - found 10416 patterns
2021-07-18 08:27:46,666 - __main__ - INFO - computing patterns for level : 9
2021-07-18 08:27:51,859 - __main__ - INFO - saving 9 level patterns
2021-07-18 08:27:51,860 - __main__ - INFO - found 3073 patterns
2021-07-18 08:27:51,860 - __main__ - INFO - computing patterns for level : 10
2021-07-18 08:27:54,047 - __main__ - INFO - saving 10 level patterns
2021-07-18 08:27:54,048 - __main__ - INFO - found 115 patterns
2021-07-18 08:27:54,048 - __main__ - INFO - computing patterns for level : 11
2021-07-18 08:27:54,253 - __main__ - INFO - saving 11 level patterns
2021-07-18 08:27:54,254 - __main__ - INFO - found 0 patterns
2021-07-18 08:27:54,254 - __main__ - INFO - computing patterns for level : 12
2021-07-18 08:27:54,339 - __main__ - INFO - saving 12 level patterns
2021-07-18 08:27:54,382 - __main__ - INFO - total time taken: 28.76385998725891
2021-07-18 08:27:54,383 - root - INFO - broadcast size:3754307
shuffle read:4190441
shuffle write:4185835
2021-07-18 08:42:08,935 - __main__ - INFO - Got the following arguments: ['our_newtest.py', '0.05', '1', '0.35', '8', '../CMineMR-Mapreduce-algorithm-to-extract-coverage-patterns-master/dataset/mushroom.txt', 'varying_mincs_mushroom_0.35_ultrmaxprodummy']
2021-07-18 08:42:14,841 - __main__ - INFO - started mining
2021-07-18 08:42:14,841 - __main__ - INFO - reading transactional data
2021-07-18 08:42:14,904 - __main__ - INFO - transactions size: 2151101
2021-07-18 08:42:14,904 - __main__ - INFO - First level mining
2021-07-18 08:42:17,103 - __main__ - INFO - Got first level patterns : 73  writing to file
2021-07-18 08:42:17,104 - __main__ - INFO - Generating second level candidateset
2021-07-18 08:42:17,397 - __main__ - INFO - saving 2 level patterns
2021-07-18 08:42:17,397 - __main__ - INFO - found 1246 patterns
2021-07-18 08:42:17,397 - __main__ - INFO - computing patterns for level : 3
2021-07-18 08:42:17,840 - __main__ - INFO - saving 3 level patterns
2021-07-18 08:42:17,841 - __main__ - INFO - found 8673 patterns
2021-07-18 08:42:17,841 - __main__ - INFO - computing patterns for level : 4
2021-07-18 08:42:18,627 - __main__ - INFO - saving 4 level patterns
2021-07-18 08:42:18,628 - __main__ - INFO - found 31193 patterns
2021-07-18 08:42:18,628 - __main__ - INFO - computing patterns for level : 5
2021-07-18 08:42:20,464 - __main__ - INFO - saving 5 level patterns
2021-07-18 08:42:20,468 - __main__ - INFO - found 65630 patterns
2021-07-18 08:42:20,468 - __main__ - INFO - computing patterns for level : 6
2021-07-18 08:42:24,055 - __main__ - INFO - saving 6 level patterns
2021-07-18 08:42:24,064 - __main__ - INFO - found 86938 patterns
2021-07-18 08:42:24,064 - __main__ - INFO - computing patterns for level : 7
2021-07-18 08:42:28,685 - __main__ - INFO - saving 7 level patterns
2021-07-18 08:42:28,695 - __main__ - INFO - found 75441 patterns
2021-07-18 08:42:28,695 - __main__ - INFO - computing patterns for level : 8
2021-07-18 08:42:32,632 - __main__ - INFO - saving 8 level patterns
2021-07-18 08:42:32,641 - __main__ - INFO - found 43413 patterns
2021-07-18 08:42:32,641 - __main__ - INFO - computing patterns for level : 9
2021-07-18 08:42:35,164 - __main__ - INFO - saving 9 level patterns
2021-07-18 08:42:35,169 - __main__ - INFO - found 16302 patterns
2021-07-18 08:42:35,169 - __main__ - INFO - computing patterns for level : 10
2021-07-18 08:42:36,313 - __main__ - INFO - saving 10 level patterns
2021-07-18 08:42:36,315 - __main__ - INFO - found 3724 patterns
2021-07-18 08:42:36,315 - __main__ - INFO - computing patterns for level : 11
2021-07-18 08:42:36,656 - __main__ - INFO - saving 11 level patterns
2021-07-18 08:42:36,656 - __main__ - INFO - found 452 patterns
2021-07-18 08:42:36,656 - __main__ - INFO - computing patterns for level : 12
2021-07-18 08:42:36,765 - __main__ - INFO - saving 12 level patterns
2021-07-18 08:42:36,765 - __main__ - INFO - found 24 patterns
2021-07-18 08:42:36,765 - __main__ - INFO - computing patterns for level : 13
2021-07-18 08:42:36,868 - __main__ - INFO - saving 13 level patterns
2021-07-18 08:42:36,868 - __main__ - INFO - found 0 patterns
2021-07-18 08:42:36,868 - __main__ - INFO - computing patterns for level : 14
2021-07-18 08:42:36,974 - __main__ - INFO - saving 14 level patterns
2021-07-18 08:42:36,982 - __main__ - INFO - total time taken: 22.140960454940796
2021-07-18 08:42:36,983 - root - INFO - broadcast size:558345
shuffle read:27570081
shuffle write:27526301
2021-07-23 20:28:36,029 - __main__ - INFO - Got the following arguments: ['our_newtest.py', '0.03', '1', '0.35', '8', '../CMineMR-Mapreduce-algorithm-to-extract-coverage-patterns-master/dataset/synthetic.txt', 'varying_mincs_mushroom_0.35_ultrmaxprodummy']
2021-07-23 20:28:40,010 - __main__ - INFO - started mining
2021-07-23 20:28:40,011 - __main__ - INFO - reading transactional data
2021-07-23 20:28:40,200 - __main__ - INFO - First level mining
2021-07-23 20:28:43,782 - __main__ - INFO - Got first level patterns : 60  writing to file
2021-07-23 20:28:43,794 - __main__ - INFO - Generating second level candidateset
2021-07-23 20:28:44,261 - __main__ - INFO - saving 2 level patterns
2021-07-23 20:28:44,262 - __main__ - INFO - found 1768 patterns
2021-07-23 20:28:44,262 - __main__ - INFO - computing patterns for level : 3
2021-07-23 20:28:47,802 - __main__ - INFO - saving 3 level patterns
2021-07-23 20:28:47,803 - __main__ - INFO - found 34076 patterns
2021-07-23 20:28:47,803 - __main__ - INFO - computing patterns for level : 4
2021-07-23 20:29:22,684 - __main__ - INFO - saving 4 level patterns
2021-07-23 20:29:22,694 - __main__ - INFO - found 481705 patterns
2021-07-23 20:29:22,695 - __main__ - INFO - computing patterns for level : 5
2021-07-23 20:36:17,217 - __main__ - INFO - saving 5 level patterns
2021-07-23 20:36:17,306 - __main__ - INFO - found 5285880 patterns
2021-07-23 20:36:17,306 - __main__ - INFO - computing patterns for level : 6
2021-07-23 20:36:25,428 - py4j.java_gateway - INFO - Error while receiving.
Traceback (most recent call last):
  File "/home/preetham_sathineni/anaconda2/envs/py37/lib/python3.7/site-packages/py4j/java_gateway.py", line 1207, in send_command
    raise Py4JNetworkError("Answer from Java side is empty")
py4j.protocol.Py4JNetworkError: Answer from Java side is empty
2021-07-23 20:36:25,430 - root - ERROR - Exception while sending command.
Traceback (most recent call last):
  File "/home/preetham_sathineni/anaconda2/envs/py37/lib/python3.7/site-packages/py4j/java_gateway.py", line 1207, in send_command
    raise Py4JNetworkError("Answer from Java side is empty")
py4j.protocol.Py4JNetworkError: Answer from Java side is empty

During handling of the above exception, another exception occurred:

Traceback (most recent call last):
  File "/home/preetham_sathineni/anaconda2/envs/py37/lib/python3.7/site-packages/py4j/java_gateway.py", line 1033, in send_command
    response = connection.send_command(command)
  File "/home/preetham_sathineni/anaconda2/envs/py37/lib/python3.7/site-packages/py4j/java_gateway.py", line 1212, in send_command
    "Error while receiving", e, proto.ERROR_ON_RECEIVE)
py4j.protocol.Py4JNetworkError: Error while receiving
2021-07-23 20:36:25,431 - py4j.java_gateway - ERROR - An error occurred while trying to connect to the Java server (127.0.0.1:42119)
Traceback (most recent call last):
  File "/home/preetham_sathineni/anaconda2/envs/py37/lib/python3.7/site-packages/py4j/java_gateway.py", line 977, in _get_connection
    connection = self.deque.pop()
IndexError: pop from an empty deque

During handling of the above exception, another exception occurred:

Traceback (most recent call last):
  File "/home/preetham_sathineni/anaconda2/envs/py37/lib/python3.7/site-packages/py4j/java_gateway.py", line 1115, in start
    self.socket.connect((self.address, self.port))
ConnectionRefusedError: [Errno 111] Connection refused
2021-07-23 20:36:25,431 - py4j.java_gateway - ERROR - An error occurred while trying to connect to the Java server (127.0.0.1:42119)
Traceback (most recent call last):
  File "/home/preetham_sathineni/anaconda2/envs/py37/lib/python3.7/site-packages/py4j/java_gateway.py", line 977, in _get_connection
    connection = self.deque.pop()
IndexError: pop from an empty deque

During handling of the above exception, another exception occurred:

Traceback (most recent call last):
  File "/home/preetham_sathineni/anaconda2/envs/py37/lib/python3.7/site-packages/py4j/java_gateway.py", line 1115, in start
    self.socket.connect((self.address, self.port))
ConnectionRefusedError: [Errno 111] Connection refused
2021-07-23 20:36:25,431 - py4j.java_gateway - ERROR - An error occurred while trying to connect to the Java server (127.0.0.1:42119)
Traceback (most recent call last):
  File "/home/preetham_sathineni/anaconda2/envs/py37/lib/python3.7/site-packages/py4j/java_gateway.py", line 977, in _get_connection
    connection = self.deque.pop()
IndexError: pop from an empty deque

During handling of the above exception, another exception occurred:

Traceback (most recent call last):
  File "/home/preetham_sathineni/anaconda2/envs/py37/lib/python3.7/site-packages/py4j/java_gateway.py", line 1115, in start
    self.socket.connect((self.address, self.port))
ConnectionRefusedError: [Errno 111] Connection refused
2021-07-23 20:36:25,432 - py4j.java_gateway - ERROR - An error occurred while trying to connect to the Java server (127.0.0.1:42119)
Traceback (most recent call last):
  File "/home/preetham_sathineni/anaconda2/envs/py37/lib/python3.7/site-packages/py4j/java_gateway.py", line 977, in _get_connection
    connection = self.deque.pop()
IndexError: pop from an empty deque

During handling of the above exception, another exception occurred:

Traceback (most recent call last):
  File "/home/preetham_sathineni/anaconda2/envs/py37/lib/python3.7/site-packages/py4j/java_gateway.py", line 1115, in start
    self.socket.connect((self.address, self.port))
ConnectionRefusedError: [Errno 111] Connection refused
2021-07-23 20:36:25,432 - py4j.java_gateway - ERROR - An error occurred while trying to connect to the Java server (127.0.0.1:42119)
Traceback (most recent call last):
  File "/home/preetham_sathineni/anaconda2/envs/py37/lib/python3.7/site-packages/py4j/java_gateway.py", line 977, in _get_connection
    connection = self.deque.pop()
IndexError: pop from an empty deque

During handling of the above exception, another exception occurred:

Traceback (most recent call last):
  File "/home/preetham_sathineni/anaconda2/envs/py37/lib/python3.7/site-packages/py4j/java_gateway.py", line 1115, in start
    self.socket.connect((self.address, self.port))
ConnectionRefusedError: [Errno 111] Connection refused
2021-07-23 20:36:25,432 - py4j.java_gateway - ERROR - An error occurred while trying to connect to the Java server (127.0.0.1:42119)
Traceback (most recent call last):
  File "/home/preetham_sathineni/anaconda2/envs/py37/lib/python3.7/site-packages/py4j/java_gateway.py", line 977, in _get_connection
    connection = self.deque.pop()
IndexError: pop from an empty deque

During handling of the above exception, another exception occurred:

Traceback (most recent call last):
  File "/home/preetham_sathineni/anaconda2/envs/py37/lib/python3.7/site-packages/py4j/java_gateway.py", line 1115, in start
    self.socket.connect((self.address, self.port))
ConnectionRefusedError: [Errno 111] Connection refused
2021-07-23 20:36:26,234 - py4j.java_gateway - ERROR - An error occurred while trying to connect to the Java server (127.0.0.1:42119)
Traceback (most recent call last):
  File "/home/preetham_sathineni/anaconda2/envs/py37/lib/python3.7/site-packages/py4j/java_gateway.py", line 977, in _get_connection
    connection = self.deque.pop()
IndexError: pop from an empty deque

During handling of the above exception, another exception occurred:

Traceback (most recent call last):
  File "/home/preetham_sathineni/anaconda2/envs/py37/lib/python3.7/site-packages/py4j/java_gateway.py", line 1115, in start
    self.socket.connect((self.address, self.port))
ConnectionRefusedError: [Errno 111] Connection refused
2021-07-23 20:36:26,234 - py4j.java_gateway - ERROR - An error occurred while trying to connect to the Java server (127.0.0.1:42119)
Traceback (most recent call last):
  File "/home/preetham_sathineni/anaconda2/envs/py37/lib/python3.7/site-packages/py4j/java_gateway.py", line 977, in _get_connection
    connection = self.deque.pop()
IndexError: pop from an empty deque

During handling of the above exception, another exception occurred:

Traceback (most recent call last):
  File "/home/preetham_sathineni/anaconda2/envs/py37/lib/python3.7/site-packages/py4j/java_gateway.py", line 1115, in start
    self.socket.connect((self.address, self.port))
ConnectionRefusedError: [Errno 111] Connection refused
2021-07-23 20:36:26,234 - py4j.java_gateway - ERROR - An error occurred while trying to connect to the Java server (127.0.0.1:42119)
Traceback (most recent call last):
  File "/home/preetham_sathineni/anaconda2/envs/py37/lib/python3.7/site-packages/py4j/java_gateway.py", line 977, in _get_connection
    connection = self.deque.pop()
IndexError: pop from an empty deque

During handling of the above exception, another exception occurred:

Traceback (most recent call last):
  File "/home/preetham_sathineni/anaconda2/envs/py37/lib/python3.7/site-packages/py4j/java_gateway.py", line 1115, in start
    self.socket.connect((self.address, self.port))
ConnectionRefusedError: [Errno 111] Connection refused
2021-07-23 20:36:26,235 - py4j.java_gateway - ERROR - An error occurred while trying to connect to the Java server (127.0.0.1:42119)
Traceback (most recent call last):
  File "/home/preetham_sathineni/anaconda2/envs/py37/lib/python3.7/site-packages/py4j/java_gateway.py", line 977, in _get_connection
    connection = self.deque.pop()
IndexError: pop from an empty deque

During handling of the above exception, another exception occurred:

Traceback (most recent call last):
  File "/home/preetham_sathineni/anaconda2/envs/py37/lib/python3.7/site-packages/py4j/java_gateway.py", line 1115, in start
    self.socket.connect((self.address, self.port))
ConnectionRefusedError: [Errno 111] Connection refused
2021-07-23 20:36:26,235 - py4j.java_gateway - ERROR - An error occurred while trying to connect to the Java server (127.0.0.1:42119)
Traceback (most recent call last):
  File "/home/preetham_sathineni/anaconda2/envs/py37/lib/python3.7/site-packages/py4j/java_gateway.py", line 977, in _get_connection
    connection = self.deque.pop()
IndexError: pop from an empty deque

During handling of the above exception, another exception occurred:

Traceback (most recent call last):
  File "/home/preetham_sathineni/anaconda2/envs/py37/lib/python3.7/site-packages/py4j/java_gateway.py", line 1115, in start
    self.socket.connect((self.address, self.port))
ConnectionRefusedError: [Errno 111] Connection refused
2021-07-23 20:36:26,235 - py4j.java_gateway - ERROR - An error occurred while trying to connect to the Java server (127.0.0.1:42119)
Traceback (most recent call last):
  File "/home/preetham_sathineni/anaconda2/envs/py37/lib/python3.7/site-packages/py4j/java_gateway.py", line 977, in _get_connection
    connection = self.deque.pop()
IndexError: pop from an empty deque

During handling of the above exception, another exception occurred:

Traceback (most recent call last):
  File "/home/preetham_sathineni/anaconda2/envs/py37/lib/python3.7/site-packages/py4j/java_gateway.py", line 1115, in start
    self.socket.connect((self.address, self.port))
ConnectionRefusedError: [Errno 111] Connection refused
2021-07-23 20:36:26,235 - py4j.java_gateway - ERROR - An error occurred while trying to connect to the Java server (127.0.0.1:42119)
Traceback (most recent call last):
  File "/home/preetham_sathineni/anaconda2/envs/py37/lib/python3.7/site-packages/py4j/java_gateway.py", line 977, in _get_connection
    connection = self.deque.pop()
IndexError: pop from an empty deque

During handling of the above exception, another exception occurred:

Traceback (most recent call last):
  File "/home/preetham_sathineni/anaconda2/envs/py37/lib/python3.7/site-packages/py4j/java_gateway.py", line 1115, in start
    self.socket.connect((self.address, self.port))
ConnectionRefusedError: [Errno 111] Connection refused
2021-07-23 20:36:26,235 - py4j.java_gateway - ERROR - An error occurred while trying to connect to the Java server (127.0.0.1:42119)
Traceback (most recent call last):
  File "/home/preetham_sathineni/anaconda2/envs/py37/lib/python3.7/site-packages/py4j/java_gateway.py", line 977, in _get_connection
    connection = self.deque.pop()
IndexError: pop from an empty deque

During handling of the above exception, another exception occurred:

Traceback (most recent call last):
  File "/home/preetham_sathineni/anaconda2/envs/py37/lib/python3.7/site-packages/py4j/java_gateway.py", line 1115, in start
    self.socket.connect((self.address, self.port))
ConnectionRefusedError: [Errno 111] Connection refused
2021-07-23 20:36:26,236 - py4j.java_gateway - ERROR - An error occurred while trying to connect to the Java server (127.0.0.1:42119)
Traceback (most recent call last):
  File "/home/preetham_sathineni/anaconda2/envs/py37/lib/python3.7/site-packages/py4j/java_gateway.py", line 977, in _get_connection
    connection = self.deque.pop()
IndexError: pop from an empty deque

During handling of the above exception, another exception occurred:

Traceback (most recent call last):
  File "/home/preetham_sathineni/anaconda2/envs/py37/lib/python3.7/site-packages/py4j/java_gateway.py", line 1115, in start
    self.socket.connect((self.address, self.port))
ConnectionRefusedError: [Errno 111] Connection refused
2021-07-23 20:36:26,236 - py4j.java_gateway - ERROR - An error occurred while trying to connect to the Java server (127.0.0.1:42119)
Traceback (most recent call last):
  File "/home/preetham_sathineni/anaconda2/envs/py37/lib/python3.7/site-packages/py4j/java_gateway.py", line 977, in _get_connection
    connection = self.deque.pop()
IndexError: pop from an empty deque

During handling of the above exception, another exception occurred:

Traceback (most recent call last):
  File "/home/preetham_sathineni/anaconda2/envs/py37/lib/python3.7/site-packages/py4j/java_gateway.py", line 1115, in start
    self.socket.connect((self.address, self.port))
ConnectionRefusedError: [Errno 111] Connection refused
2021-07-23 20:36:26,236 - py4j.java_gateway - ERROR - An error occurred while trying to connect to the Java server (127.0.0.1:42119)
Traceback (most recent call last):
  File "/home/preetham_sathineni/anaconda2/envs/py37/lib/python3.7/site-packages/py4j/java_gateway.py", line 977, in _get_connection
    connection = self.deque.pop()
IndexError: pop from an empty deque

During handling of the above exception, another exception occurred:

Traceback (most recent call last):
  File "/home/preetham_sathineni/anaconda2/envs/py37/lib/python3.7/site-packages/py4j/java_gateway.py", line 1115, in start
    self.socket.connect((self.address, self.port))
ConnectionRefusedError: [Errno 111] Connection refused
2021-07-23 20:36:26,236 - py4j.java_gateway - ERROR - An error occurred while trying to connect to the Java server (127.0.0.1:42119)
Traceback (most recent call last):
  File "/home/preetham_sathineni/anaconda2/envs/py37/lib/python3.7/site-packages/py4j/java_gateway.py", line 977, in _get_connection
    connection = self.deque.pop()
IndexError: pop from an empty deque

During handling of the above exception, another exception occurred:

Traceback (most recent call last):
  File "/home/preetham_sathineni/anaconda2/envs/py37/lib/python3.7/site-packages/py4j/java_gateway.py", line 1115, in start
    self.socket.connect((self.address, self.port))
ConnectionRefusedError: [Errno 111] Connection refused
2021-07-23 20:36:26,237 - py4j.java_gateway - ERROR - An error occurred while trying to connect to the Java server (127.0.0.1:42119)
Traceback (most recent call last):
  File "/home/preetham_sathineni/anaconda2/envs/py37/lib/python3.7/site-packages/py4j/java_gateway.py", line 977, in _get_connection
    connection = self.deque.pop()
IndexError: pop from an empty deque

During handling of the above exception, another exception occurred:

Traceback (most recent call last):
  File "/home/preetham_sathineni/anaconda2/envs/py37/lib/python3.7/site-packages/py4j/java_gateway.py", line 1115, in start
    self.socket.connect((self.address, self.port))
ConnectionRefusedError: [Errno 111] Connection refused
2021-07-23 20:36:26,237 - py4j.java_gateway - ERROR - An error occurred while trying to connect to the Java server (127.0.0.1:42119)
Traceback (most recent call last):
  File "/home/preetham_sathineni/anaconda2/envs/py37/lib/python3.7/site-packages/py4j/java_gateway.py", line 977, in _get_connection
    connection = self.deque.pop()
IndexError: pop from an empty deque

During handling of the above exception, another exception occurred:

Traceback (most recent call last):
  File "/home/preetham_sathineni/anaconda2/envs/py37/lib/python3.7/site-packages/py4j/java_gateway.py", line 1115, in start
    self.socket.connect((self.address, self.port))
ConnectionRefusedError: [Errno 111] Connection refused
2021-07-23 20:36:26,237 - py4j.java_gateway - ERROR - An error occurred while trying to connect to the Java server (127.0.0.1:42119)
Traceback (most recent call last):
  File "/home/preetham_sathineni/anaconda2/envs/py37/lib/python3.7/site-packages/py4j/java_gateway.py", line 977, in _get_connection
    connection = self.deque.pop()
IndexError: pop from an empty deque

During handling of the above exception, another exception occurred:

Traceback (most recent call last):
  File "/home/preetham_sathineni/anaconda2/envs/py37/lib/python3.7/site-packages/py4j/java_gateway.py", line 1115, in start
    self.socket.connect((self.address, self.port))
ConnectionRefusedError: [Errno 111] Connection refused
2021-07-23 20:36:26,237 - py4j.java_gateway - ERROR - An error occurred while trying to connect to the Java server (127.0.0.1:42119)
Traceback (most recent call last):
  File "/home/preetham_sathineni/anaconda2/envs/py37/lib/python3.7/site-packages/py4j/java_gateway.py", line 977, in _get_connection
    connection = self.deque.pop()
IndexError: pop from an empty deque

During handling of the above exception, another exception occurred:

Traceback (most recent call last):
  File "/home/preetham_sathineni/anaconda2/envs/py37/lib/python3.7/site-packages/py4j/java_gateway.py", line 1115, in start
    self.socket.connect((self.address, self.port))
ConnectionRefusedError: [Errno 111] Connection refused
2021-07-23 20:36:26,237 - py4j.java_gateway - ERROR - An error occurred while trying to connect to the Java server (127.0.0.1:42119)
Traceback (most recent call last):
  File "/home/preetham_sathineni/anaconda2/envs/py37/lib/python3.7/site-packages/py4j/java_gateway.py", line 977, in _get_connection
    connection = self.deque.pop()
IndexError: pop from an empty deque

During handling of the above exception, another exception occurred:

Traceback (most recent call last):
  File "/home/preetham_sathineni/anaconda2/envs/py37/lib/python3.7/site-packages/py4j/java_gateway.py", line 1115, in start
    self.socket.connect((self.address, self.port))
ConnectionRefusedError: [Errno 111] Connection refused
2021-07-25 00:32:48,989 - __main__ - INFO - Got the following arguments: ['our_newtest.py', '0.04', '1', '0.35', '16', '../CMineMR-Mapreduce-algorithm-to-extract-coverage-patterns-master/dataset/mushroom.txt', 'varying_mincs_mushroom_0.35_ultrmaxprodummy']
2021-07-25 00:32:55,353 - __main__ - INFO - started mining
2021-07-25 00:32:55,353 - __main__ - INFO - reading transactional data
2021-07-25 00:32:55,379 - __main__ - INFO - First level mining
2021-07-25 00:32:57,456 - __main__ - INFO - Got first level patterns : 79  writing to file
2021-07-25 00:32:57,457 - __main__ - INFO - Generating second level candidateset
2021-07-25 00:32:57,739 - __main__ - INFO - saving 2 level patterns
2021-07-25 00:32:57,739 - __main__ - INFO - found 1555 patterns
2021-07-25 00:32:57,739 - __main__ - INFO - computing patterns for level : 3
2021-07-25 00:32:58,137 - __main__ - INFO - saving 3 level patterns
2021-07-25 00:32:58,138 - __main__ - INFO - found 13512 patterns
2021-07-25 00:32:58,138 - __main__ - INFO - computing patterns for level : 4
2021-07-25 00:32:58,955 - __main__ - INFO - saving 4 level patterns
2021-07-25 00:32:58,958 - __main__ - INFO - found 64318 patterns
2021-07-25 00:32:58,958 - __main__ - INFO - computing patterns for level : 5
2021-07-25 00:33:01,090 - __main__ - INFO - saving 5 level patterns
2021-07-25 00:33:01,104 - __main__ - INFO - found 187452 patterns
2021-07-25 00:33:01,104 - __main__ - INFO - computing patterns for level : 6
2021-07-25 00:33:06,779 - __main__ - INFO - saving 6 level patterns
2021-07-25 00:33:06,823 - __main__ - INFO - found 359377 patterns
2021-07-25 00:33:06,823 - __main__ - INFO - computing patterns for level : 7
2021-07-25 00:33:16,148 - __main__ - INFO - saving 7 level patterns
2021-07-25 00:33:16,197 - __main__ - INFO - found 477651 patterns
2021-07-25 00:33:16,198 - __main__ - INFO - computing patterns for level : 8
2021-07-25 00:33:28,721 - __main__ - INFO - saving 8 level patterns
2021-07-25 00:33:28,785 - __main__ - INFO - found 453273 patterns
2021-07-25 00:33:28,785 - __main__ - INFO - computing patterns for level : 9
2021-07-25 00:33:40,937 - __main__ - INFO - saving 9 level patterns
2021-07-25 00:33:40,994 - __main__ - INFO - found 310339 patterns
2021-07-25 00:33:40,995 - __main__ - INFO - computing patterns for level : 10
2021-07-25 00:33:49,889 - __main__ - INFO - saving 10 level patterns
2021-07-25 00:33:49,921 - __main__ - INFO - found 152642 patterns
2021-07-25 00:33:49,922 - __main__ - INFO - computing patterns for level : 11
2021-07-25 00:33:55,013 - __main__ - INFO - saving 11 level patterns
2021-07-25 00:33:55,029 - __main__ - INFO - found 52882 patterns
2021-07-25 00:33:55,029 - __main__ - INFO - computing patterns for level : 12
2021-07-25 00:33:57,056 - __main__ - INFO - saving 12 level patterns
2021-07-25 00:33:57,060 - __main__ - INFO - found 12288 patterns
2021-07-25 00:33:57,060 - __main__ - INFO - computing patterns for level : 13
2021-07-25 00:33:57,645 - __main__ - INFO - saving 13 level patterns
2021-07-25 00:33:57,646 - __main__ - INFO - found 1714 patterns
2021-07-25 00:33:57,646 - __main__ - INFO - computing patterns for level : 14
2021-07-25 00:33:57,849 - __main__ - INFO - saving 14 level patterns
2021-07-25 00:33:57,850 - __main__ - INFO - found 108 patterns
2021-07-25 00:33:57,850 - __main__ - INFO - computing patterns for level : 15
2021-07-25 00:33:57,929 - __main__ - INFO - saving 15 level patterns
2021-07-25 00:33:57,929 - __main__ - INFO - found 0 patterns
2021-07-25 00:33:57,929 - __main__ - INFO - computing patterns for level : 16
2021-07-25 00:33:58,031 - __main__ - INFO - saving 16 level patterns
2021-07-25 00:33:58,040 - __main__ - INFO - total time taken: 62.68690466880798
2021-07-25 00:33:58,041 - root - INFO - broadcast size:0
shuffle read:0
shuffle write:0
